<sdf version='1.6'>
  <world name='default'>
    <light name='sun' type='directional'>
      <cast_shadows>1</cast_shadows>
      <pose frame=''>0 0 10 0 -0 0</pose>
      <diffuse>0.8 0.8 0.8 1</diffuse>
      <specular>0.1 0.1 0.1 1</specular>
      <attenuation>
        <range>1000</range>
        <constant>0.9</constant>
        <linear>0.01</linear>
        <quadratic>0.001</quadratic>
      </attenuation>
      <direction>-0.5 0.5 -1</direction>
    </light>
    <model name='ground_plane'>
      <static>1</static>
      <link name='link'>
        <collision name='collision'>
          <geometry>
            <plane>
              <normal>0 0 1</normal>
              <size>100 100</size>
            </plane>
          </geometry>
          <surface>
            <friction>
              <ode>
                <mu>100</mu>
                <mu2>50</mu2>
              </ode>
              <torsional>
                <ode/>
              </torsional>
            </friction>
            <contact>
              <ode/>
            </contact>
            <bounce/>
          </surface>
          <max_contacts>10</max_contacts>
        </collision>
        <visual name='visual'>
          <cast_shadows>0</cast_shadows>
          <geometry>
            <plane>
              <normal>0 0 1</normal>
              <size>100 100</size>
            </plane>
          </geometry>
          <material>
            <script>
              <uri>file://media/materials/scripts/gazebo.material</uri>
              <name>Gazebo/Grey</name>
            </script>
          </material>
        </visual>
        <self_collide>0</self_collide>
        <kinematic>0</kinematic>
      </link>
    </model>
    <gravity>0 0 -9.8</gravity>
    <magnetic_field>6e-06 2.3e-05 -4.2e-05</magnetic_field>
    <atmosphere type='adiabatic'/>
    <physics name='default_physics' default='0' type='ode'>
      <max_step_size>0.001</max_step_size>
      <real_time_factor>1</real_time_factor>
      <real_time_update_rate>1000</real_time_update_rate>
    </physics>
    <scene>
      <ambient>0.4 0.4 0.4 1</ambient>
      <background>0.7 0.7 0.7 1</background>
      <shadows>1</shadows>
    </scene>
    <spherical_coordinates>
      <surface_model>EARTH_WGS84</surface_model>
      <latitude_deg>0</latitude_deg>
      <longitude_deg>0</longitude_deg>
      <elevation>0</elevation>
      <heading_deg>0</heading_deg>
    </spherical_coordinates>
    <model name='iCub'>
      <pose frame=''>0.076309 -0.081041 0.6 0 -0 3.14</pose>
      <link name='root_link'>
        <pose frame=''>0 0 0 0 -0 0</pose>
        <inertial>
          <pose frame=''>0 0 0 0 -0 0</pose>
          <mass>4.72</mass>
          <inertia>
            <ixx>0.01</ixx>
            <ixy>0</ixy>
            <ixz>0</ixz>
            <iyy>0.01</iyy>
            <iyz>0</iyz>
            <izz>0.01</izz>
          </inertia>
        </inertial>
        <collision name='root_link_collision'>
          <pose frame=''>0 0 0 0 -0 0</pose>
          <geometry>
            <mesh>
              <scale>1 1 1</scale>
              <uri>model://icub/meshes/collision/icub_simple_collision_root_link.dae</uri>
            </mesh>
          </geometry>
          <max_contacts>10</max_contacts>
          <surface>
            <contact>
              <ode/>
            </contact>
            <bounce/>
            <friction>
              <torsional>
                <ode/>
              </torsional>
              <ode/>
            </friction>
          </surface>
        </collision>
        <visual name='root_link_visual'>
          <pose frame=''>0 0 0 0 -0 0</pose>
          <geometry>
            <mesh>
              <scale>1 1 1</scale>
              <uri>model://icub/meshes/visual/icub_root_link.dae</uri>
            </mesh>
          </geometry>
        </visual>
        <self_collide>0</self_collide>
        <kinematic>0</kinematic>
      </link>
      <link name='l_hip_1'>
        <pose frame=''>0 -0.0681 -0.1199 3e-06 1.57079 3.14159</pose>
        <inertial>
          <pose frame=''>0 -0.0782 0 0 -0 0</pose>
          <mass>0.754</mass>
          <inertia>
            <ixx>0.01</ixx>
            <ixy>2.059e-06</ixy>
            <ixz>1.451e-06</ixz>
            <iyy>0.01</iyy>
            <iyz>1.545e-06</iyz>
            <izz>0.01</izz>
          </inertia>
        </inertial>
        <collision name='l_hip_1_collision'>
          <pose frame=''>0 0 0 -0.785403 1.57079 -2.35619</pose>
          <geometry>
            <mesh>
              <scale>1 1 1</scale>
              <uri>model://icub/meshes/collision/icub_simple_collision_l_hip_1.dae</uri>
            </mesh>
          </geometry>
          <max_contacts>10</max_contacts>
          <surface>
            <contact>
              <ode/>
            </contact>
            <bounce/>
            <friction>
              <torsional>
                <ode/>
              </torsional>
              <ode/>
            </friction>
          </surface>
        </collision>
        <visual name='l_hip_1_visual'>
          <pose frame=''>0 0 0 -0.785403 1.57079 -2.35619</pose>
          <geometry>
            <mesh>
              <scale>1 1 1</scale>
              <uri>model://icub/meshes/visual/icub_l_hip_1.dae</uri>
            </mesh>
          </geometry>
        </visual>
        <self_collide>0</self_collide>
        <kinematic>0</kinematic>
      </link>
      <joint name='l_hip_pitch' type='revolute'>
        <child>l_hip_1</child>
        <parent>root_link</parent>
        <axis>
          <xyz>3e-06 1 0</xyz>
          <limit>
            <lower>-0.767945</lower>
            <upper>2.30383</upper>
            <effort>84</effort>
            <velocity>100</velocity>
          </limit>
          <dynamics>
            <damping>1</damping>
            <friction>0</friction>
            <spring_reference>0</spring_reference>
            <spring_stiffness>0</spring_stiffness>
          </dynamics>
          <use_parent_model_frame>1</use_parent_model_frame>
        </axis>
      </joint>
      <link name='l_hip_2'>
        <pose frame=''>0 -0.0681 -0.1199 3.14159 -7e-06 3.14159</pose>
        <inertial>
          <pose frame=''>0 0 0.03045 0 -0 0</pose>
          <mass>0.526</mass>
          <inertia>
            <ixx>0.01</ixx>
            <ixy>-7.4e-08</ixy>
            <ixz>1.0835e-05</ixz>
            <iyy>0.01</iyy>
            <iyz>-6.2e-08</iyz>
            <izz>0.01</izz>
          </inertia>
        </inertial>
        <collision name='l_hip_2_collision'>
          <pose frame=''>0 0 0 0.785363 -1.57079 2.35623</pose>
          <geometry>
            <mesh>
              <scale>1 1 1</scale>
              <uri>model://icub/meshes/collision/icub_simple_collision_l_hip_2.dae</uri>
            </mesh>
          </geometry>
          <max_contacts>10</max_contacts>
          <surface>
            <contact>
              <ode/>
            </contact>
            <bounce/>
            <friction>
              <torsional>
                <ode/>
              </torsional>
              <ode/>
            </friction>
          </surface>
        </collision>
        <visual name='l_hip_2_visual'>
          <pose frame=''>0 0 0 0.785363 -1.57079 2.35623</pose>
          <geometry>
            <mesh>
              <scale>1 1 1</scale>
              <uri>model://icub/meshes/visual/icub_l_hip_2.dae</uri>
            </mesh>
          </geometry>
        </visual>
        <self_collide>0</self_collide>
        <kinematic>0</kinematic>
      </link>
      <joint name='l_hip_roll' type='revolute'>
        <child>l_hip_2</child>
        <parent>l_hip_1</parent>
        <axis>
          <xyz>-1 3e-06 7e-06</xyz>
          <limit>
            <lower>-0.296706</lower>
            <upper>2.07694</upper>
            <effort>84</effort>
            <velocity>100</velocity>
          </limit>
          <dynamics>
            <damping>1</damping>
            <friction>0</friction>
            <spring_reference>0</spring_reference>
            <spring_stiffness>0</spring_stiffness>
          </dynamics>
          <use_parent_model_frame>1</use_parent_model_frame>
        </axis>
      </joint>
      <link name='l_hip_3'>
        <pose frame=''>-0 -0.0681 -0.1864 3.14159 -7e-06 3.14159</pose>
        <inertial>
          <pose frame=''>0 0 0 0 -0 0</pose>
          <mass>0.1</mass>
          <inertia>
            <ixx>0.01</ixx>
            <ixy>0</ixy>
            <ixz>0</ixz>
            <iyy>0.01</iyy>
            <iyz>0</iyz>
            <izz>0.01</izz>
          </inertia>
        </inertial>
        <self_collide>0</self_collide>
        <kinematic>0</kinematic>
      </link>
      <joint name='l_leg_ft_sensor' type='revolute'>
        <child>l_hip_3</child>
        <parent>l_hip_2</parent>
        <axis>
          <xyz>0 0 0</xyz>
          <limit>
            <lower>0</lower>
            <upper>0</upper>
            <effort>0</effort>
            <velocity>0</velocity>
          </limit>
          <dynamics>
            <spring_reference>0</spring_reference>
            <spring_stiffness>0</spring_stiffness>
          </dynamics>
          <use_parent_model_frame>1</use_parent_model_frame>
        </axis>
        <sensor name='left_leg_ft' type='force_torque'>
          <always_on>1</always_on>
          <update_rate>100</update_rate>
          <pose frame=''>0 0 0 0 -0 0</pose>
          <plugin name='left_leg_ft_plugin' filename='libgazebo_yarp_forcetorque.so'>
            <yarpConfigurationFile>model://icub/conf/FT/gazebo_icub_left_leg_ft.ini</yarpConfigurationFile>
          </plugin>
        </sensor>
      </joint>
      <link name='l_upper_leg'>
        <pose frame=''>0 -0.0681 -0.1199 1.57079 -7e-06 3.14159</pose>
        <inertial>
          <pose frame=''>0.00144 -0.15943 -0.00039 0 -0 0</pose>
          <mass>2.175</mass>
          <inertia>
            <ixx>0.01</ixx>
            <ixy>-6.726e-05</ixy>
            <ixz>2.267e-06</ixz>
            <iyy>0.01</iyy>
            <iyz>3.63726e-05</iyz>
            <izz>0.01</izz>
          </inertia>
        </inertial>
        <collision name='l_upper_leg_collision'>
          <pose frame=''>0 0 0 -2.67797 1.57079 -1.10716</pose>
          <geometry>
            <mesh>
              <scale>1 1 1</scale>
              <uri>model://icub/meshes/collision/icub_simple_collision_l_thigh.dae</uri>
            </mesh>
          </geometry>
          <max_contacts>10</max_contacts>
          <surface>
            <contact>
              <ode/>
            </contact>
            <bounce/>
            <friction>
              <torsional>
                <ode/>
              </torsional>
              <ode/>
            </friction>
          </surface>
        </collision>
        <visual name='l_upper_leg_visual'>
          <pose frame=''>0 0 0 -2.67797 1.57079 -1.10716</pose>
          <geometry>
            <mesh>
              <scale>1 1 1</scale>
              <uri>model://icub/meshes/visual/icub_l_thigh.dae</uri>
            </mesh>
          </geometry>
        </visual>
        <self_collide>0</self_collide>
        <kinematic>0</kinematic>
      </link>
      <joint name='l_hip_yaw' type='revolute'>
        <child>l_upper_leg</child>
        <parent>l_hip_3</parent>
        <axis>
          <xyz>7e-06 -6e-06 1</xyz>
          <limit>
            <lower>-1.37881</lower>
            <upper>1.37881</upper>
            <effort>40</effort>
            <velocity>100</velocity>
          </limit>
          <dynamics>
            <damping>1</damping>
            <friction>0</friction>
            <spring_reference>0</spring_reference>
            <spring_stiffness>0</spring_stiffness>
          </dynamics>
          <use_parent_model_frame>1</use_parent_model_frame>
        </axis>
      </joint>
      <link name='l_lower_leg'>
        <pose frame=''>-2e-06 -0.068099 -0.3435 2.09198 -1.57078 -0.521189</pose>
        <inertial>
          <pose frame=''>-0.1071 0.00182 0.00211 0 -0 0</pose>
          <mass>1.264</mass>
          <inertia>
            <ixx>0.01</ixx>
            <ixy>-0.000185699</ixy>
            <ixz>-6.3147e-05</ixz>
            <iyy>0.01</iyy>
            <iyz>7.86e-07</iyz>
            <izz>0.01</izz>
          </inertia>
        </inertial>
        <collision name='l_lower_leg_collision'>
          <pose frame=''>0 0 0 -3.14159 -0 1.5708</pose>
          <geometry>
            <mesh>
              <scale>1 1 1</scale>
              <uri>model://icub/meshes/collision/icub_simple_collision_l_shank.dae</uri>
            </mesh>
          </geometry>
          <max_contacts>10</max_contacts>
          <surface>
            <contact>
              <ode/>
            </contact>
            <bounce/>
            <friction>
              <torsional>
                <ode/>
              </torsional>
              <ode/>
            </friction>
          </surface>
        </collision>
        <visual name='l_lower_leg_visual'>
          <pose frame=''>0 0 0 -3.14159 -0 1.5708</pose>
          <geometry>
            <mesh>
              <scale>1 1 1</scale>
              <uri>model://icub/meshes/visual/icub_l_shank.dae</uri>
            </mesh>
          </geometry>
        </visual>
        <self_collide>0</self_collide>
        <kinematic>0</kinematic>
      </link>
      <joint name='l_knee' type='revolute'>
        <child>l_lower_leg</child>
        <parent>l_upper_leg</parent>
        <axis>
          <xyz>5e-06 1 6e-06</xyz>
          <limit>
            <lower>-2.18166</lower>
            <upper>0.401426</upper>
            <effort>30</effort>
            <velocity>100</velocity>
          </limit>
          <dynamics>
            <damping>1</damping>
            <friction>0</friction>
            <spring_reference>0</spring_reference>
            <spring_stiffness>0</spring_stiffness>
          </dynamics>
          <use_parent_model_frame>1</use_parent_model_frame>
        </axis>
      </joint>
      <link name='l_ankle_1'>
        <pose frame=''>-4e-06 -0.068097 -0.5565 0.52118 -1.57078 -0.521189</pose>
        <inertial>
          <pose frame=''>-0.0054 0.00163 0.0172 0 -0 0</pose>
          <mass>0.746</mass>
          <inertia>
            <ixx>0.01</ixx>
            <ixy>-7.081e-06</ixy>
            <ixz>4.1421e-05</ixz>
            <iyy>0.01</iyy>
            <iyz>2.0817e-05</iyz>
            <izz>0.01</izz>
          </inertia>
        </inertial>
        <collision name='l_ankle_1_collision'>
          <pose frame=''>0 -0 0 1.5708 -0 0</pose>
          <geometry>
            <mesh>
              <scale>1 1 1</scale>
              <uri>model://icub/meshes/collision/icub_simple_collision_l_ankle_1.dae</uri>
            </mesh>
          </geometry>
          <max_contacts>10</max_contacts>
          <surface>
            <contact>
              <ode/>
            </contact>
            <bounce/>
            <friction>
              <torsional>
                <ode/>
              </torsional>
              <ode/>
            </friction>
          </surface>
        </collision>
        <visual name='l_ankle_1_visual'>
          <pose frame=''>0 -0 0 1.5708 -0 0</pose>
          <geometry>
            <mesh>
              <scale>1 1 1</scale>
              <uri>model://icub/meshes/visual/icub_l_ankle_1.dae</uri>
            </mesh>
          </geometry>
        </visual>
        <self_collide>0</self_collide>
        <kinematic>0</kinematic>
      </link>
      <joint name='l_ankle_pitch' type='revolute'>
        <child>l_ankle_1</child>
        <parent>l_lower_leg</parent>
        <axis>
          <xyz>-9e-06 -1 -6e-06</xyz>
          <limit>
            <lower>-0.733038</lower>
            <upper>0.366519</upper>
            <effort>24</effort>
            <velocity>100</velocity>
          </limit>
          <dynamics>
            <damping>1</damping>
            <friction>0</friction>
            <spring_reference>0</spring_reference>
            <spring_stiffness>0</spring_stiffness>
          </dynamics>
          <use_parent_model_frame>1</use_parent_model_frame>
        </axis>
      </joint>
      <link name='l_ankle_2'>
        <pose frame=''>-4e-06 -0.068097 -0.5565 3.14159 -7e-06 3.14158</pose>
        <inertial>
          <pose frame=''>0 0 0.037 0 -0 0</pose>
          <mass>0.2675</mass>
          <inertia>
            <ixx>0.01</ixx>
            <ixy>0</ixy>
            <ixz>0</ixz>
            <iyy>0.01</iyy>
            <iyz>0</iyz>
            <izz>0.01</izz>
          </inertia>
        </inertial>
        <self_collide>0</self_collide>
        <kinematic>0</kinematic>
      </link>
      <joint name='l_ankle_roll' type='revolute'>
        <child>l_ankle_2</child>
        <parent>l_ankle_1</parent>
        <axis>
          <xyz>-1 9e-06 7e-06</xyz>
          <limit>
            <lower>-0.418879</lower>
            <upper>0.418879</upper>
            <effort>11</effort>
            <velocity>100</velocity>
          </limit>
          <dynamics>
            <damping>1</damping>
            <friction>0</friction>
            <spring_reference>0</spring_reference>
            <spring_stiffness>0</spring_stiffness>
          </dynamics>
          <use_parent_model_frame>1</use_parent_model_frame>
        </axis>
      </joint>
      <link name='l_foot'>
        <pose frame=''>-4e-06 -0.068097 -0.5935 3.14159 -7e-06 3.14158</pose>
        <inertial>
          <pose frame=''>0.024069 -0.000614 -0.028415 0 -0 0</pose>
          <mass>0.5935</mass>
          <inertia>
            <ixx>0.01</ixx>
            <ixy>-4.51893e-06</ixy>
            <ixz>0.000567785</ixz>
            <iyy>0.01</iyy>
            <iyz>-6.62361e-07</iyz>
            <izz>0.01</izz>
          </inertia>
        </inertial>
        <collision name='l_foot_collision'>
          <pose frame=''>0.03 0 -0.01 0 -0 0</pose>
          <geometry>
            <box>
              <size>0.15 0.07 0.03</size>
            </box>
          </geometry>
          <max_contacts>4</max_contacts>
          <surface>
            <contact>
              <ode>
                <soft_erp>0.2</soft_erp>
                <soft_cfm>0</soft_cfm>
                <kp>1.8e+07</kp>
                <kd>100</kd>
                <max_vel>100</max_vel>
                <min_depth>0.0001</min_depth>
              </ode>
            </contact>
            <friction>
              <ode>
                <mu>1</mu>
                <mu2>1</mu2>
                <fdir1>0 0 0</fdir1>
                <slip1>0</slip1>
                <slip2>0</slip2>
              </ode>
              <torsional>
                <ode/>
              </torsional>
            </friction>
            <bounce>
              <restitution_coefficient>0</restitution_coefficient>
              <threshold>100000</threshold>
            </bounce>
          </surface>
        </collision>
        <visual name='l_foot_visual'>
          <pose frame=''>0 -0 -0.037 -0.785403 1.57079 -0.785403</pose>
          <geometry>
            <mesh>
              <scale>1 1 1</scale>
              <uri>model://icub/meshes/visual/icub_l_foot.dae</uri>
            </mesh>
          </geometry>
        </visual>
        <self_collide>0</self_collide>
        <kinematic>0</kinematic>
      </link>
      <joint name='l_foot_ft_sensor' type='revolute'>
        <child>l_foot</child>
        <parent>l_ankle_2</parent>
        <axis>
          <xyz>0 0 0</xyz>
          <limit>
            <lower>0</lower>
            <upper>0</upper>
            <effort>0</effort>
            <velocity>0</velocity>
          </limit>
          <dynamics>
            <spring_reference>0</spring_reference>
            <spring_stiffness>0</spring_stiffness>
          </dynamics>
          <use_parent_model_frame>1</use_parent_model_frame>
        </axis>
        <sensor name='left_foot_ft' type='force_torque'>
          <always_on>1</always_on>
          <update_rate>100</update_rate>
          <pose frame=''>0 0 0 0 -0 0</pose>
          <plugin name='left_foot_ft_plugin' filename='libgazebo_yarp_forcetorque.so'>
            <yarpConfigurationFile>model://icub/conf/FT/gazebo_icub_left_foot_ft.ini</yarpConfigurationFile>
          </plugin>
        </sensor>
      </joint>
      <link name='r_hip_1'>
        <pose frame=''>0 0.0681 -0.1199 3.14159 1.57079 -3.14159</pose>
        <inertial>
          <pose frame=''>0 -0.0782 0 0 -0 0</pose>
          <mass>0.754</mass>
          <inertia>
            <ixx>0.01</ixx>
            <ixy>0</ixy>
            <ixz>0</ixz>
            <iyy>0.01</iyy>
            <iyz>0</iyz>
            <izz>0.01</izz>
          </inertia>
        </inertial>
        <collision name='r_hip_1_collision'>
          <pose frame=''>0 0 0 1.76819 -1.57079 2.76109</pose>
          <geometry>
            <mesh>
              <scale>1 1 1</scale>
              <uri>model://icub/meshes/collision/icub_simple_collision_r_hip_1.dae</uri>
            </mesh>
          </geometry>
          <max_contacts>10</max_contacts>
          <surface>
            <contact>
              <ode/>
            </contact>
            <bounce/>
            <friction>
              <torsional>
                <ode/>
              </torsional>
              <ode/>
            </friction>
          </surface>
        </collision>
        <visual name='r_hip_1_visual'>
          <pose frame=''>0 0 0 1.76819 -1.57079 2.76109</pose>
          <geometry>
            <mesh>
              <scale>1 1 1</scale>
              <uri>model://icub/meshes/visual/icub_r_hip_1.dae</uri>
            </mesh>
          </geometry>
        </visual>
        <self_collide>0</self_collide>
        <kinematic>0</kinematic>
      </link>
      <joint name='r_hip_pitch' type='revolute'>
        <child>r_hip_1</child>
        <parent>root_link</parent>
        <axis>
          <xyz>0 1 0</xyz>
          <limit>
            <lower>-0.767945</lower>
            <upper>2.30383</upper>
            <effort>84</effort>
            <velocity>100</velocity>
          </limit>
          <dynamics>
            <damping>1</damping>
            <friction>0</friction>
            <spring_reference>0</spring_reference>
            <spring_stiffness>0</spring_stiffness>
          </dynamics>
          <use_parent_model_frame>1</use_parent_model_frame>
        </axis>
      </joint>
      <link name='r_hip_2'>
        <pose frame=''>0 0.0681 -0.1199 -3.14159 -7e-06 -3.14159</pose>
        <inertial>
          <pose frame=''>0 0 0.03045 0 -0 0</pose>
          <mass>0.526</mass>
          <inertia>
            <ixx>0.01</ixx>
            <ixy>0</ixy>
            <ixz>0</ixz>
            <iyy>0.01</iyy>
            <iyz>0</iyz>
            <izz>0.01</izz>
          </inertia>
        </inertial>
        <collision name='r_hip_2_collision'>
          <pose frame=''>0 0 0 -2.35627 -1.57079 2.35627</pose>
          <geometry>
            <mesh>
              <scale>1 1 1</scale>
              <uri>model://icub/meshes/collision/icub_simple_collision_r_hip_2.dae</uri>
            </mesh>
          </geometry>
          <max_contacts>10</max_contacts>
          <surface>
            <contact>
              <ode/>
            </contact>
            <bounce/>
            <friction>
              <torsional>
                <ode/>
              </torsional>
              <ode/>
            </friction>
          </surface>
        </collision>
        <visual name='r_hip_2_visual'>
          <pose frame=''>0 0 0 -2.35627 -1.57079 2.35627</pose>
          <geometry>
            <mesh>
              <scale>1 1 1</scale>
              <uri>model://icub/meshes/visual/icub_r_hip_2.dae</uri>
            </mesh>
          </geometry>
        </visual>
        <self_collide>0</self_collide>
        <kinematic>0</kinematic>
      </link>
      <joint name='r_hip_roll' type='revolute'>
        <child>r_hip_2</child>
        <parent>r_hip_1</parent>
        <axis>
          <xyz>1 0 -7e-06</xyz>
          <limit>
            <lower>-0.296706</lower>
            <upper>2.07694</upper>
            <effort>84</effort>
            <velocity>100</velocity>
          </limit>
          <dynamics>
            <damping>1</damping>
            <friction>0</friction>
            <spring_reference>0</spring_reference>
            <spring_stiffness>0</spring_stiffness>
          </dynamics>
          <use_parent_model_frame>1</use_parent_model_frame>
        </axis>
      </joint>
      <link name='r_hip_3'>
        <pose frame=''>-0 0.0681 -0.1864 -3.14159 -7e-06 -3.14159</pose>
        <inertial>
          <pose frame=''>0 0 0 0 -0 0</pose>
          <mass>0.1</mass>
          <inertia>
            <ixx>0.01</ixx>
            <ixy>0</ixy>
            <ixz>0</ixz>
            <iyy>0.01</iyy>
            <iyz>0</iyz>
            <izz>0.01</izz>
          </inertia>
        </inertial>
        <self_collide>0</self_collide>
        <kinematic>0</kinematic>
      </link>
      <joint name='r_leg_ft_sensor' type='revolute'>
        <child>r_hip_3</child>
        <parent>r_hip_2</parent>
        <axis>
          <xyz>0 0 0</xyz>
          <limit>
            <lower>0</lower>
            <upper>0</upper>
            <effort>0</effort>
            <velocity>0</velocity>
          </limit>
          <dynamics>
            <spring_reference>0</spring_reference>
            <spring_stiffness>0</spring_stiffness>
          </dynamics>
          <use_parent_model_frame>1</use_parent_model_frame>
        </axis>
        <sensor name='right_leg_ft' type='force_torque'>
          <always_on>1</always_on>
          <update_rate>100</update_rate>
          <pose frame=''>0 0 0 0 -0 0</pose>
          <plugin name='right_leg_ft_plugin' filename='libgazebo_yarp_forcetorque.so'>
            <yarpConfigurationFile>model://icub/conf/FT/gazebo_icub_right_leg_ft.ini</yarpConfigurationFile>
          </plugin>
        </sensor>
      </joint>
      <link name='r_upper_leg'>
        <pose frame=''>0 0.0681 -0.1199 1.57079 -7e-06 3.14159</pose>
        <inertial>
          <pose frame=''>0.00144 -0.15943 0.00039 0 -0 0</pose>
          <mass>2.175</mass>
          <inertia>
            <ixx>0.01</ixx>
            <ixy>0</ixy>
            <ixz>0</ixz>
            <iyy>0.01</iyy>
            <iyz>-2.71051e-20</iyz>
            <izz>0.01</izz>
          </inertia>
        </inertial>
        <collision name='r_upper_leg_collision'>
          <pose frame=''>0 0 0 1.57087 -1.57079 -7.3e-05</pose>
          <geometry>
            <mesh>
              <scale>1 1 1</scale>
              <uri>model://icub/meshes/collision/icub_simple_collision_r_thigh.dae</uri>
            </mesh>
          </geometry>
          <max_contacts>10</max_contacts>
          <surface>
            <contact>
              <ode/>
            </contact>
            <bounce/>
            <friction>
              <torsional>
                <ode/>
              </torsional>
              <ode/>
            </friction>
          </surface>
        </collision>
        <visual name='r_upper_leg_visual'>
          <pose frame=''>0 0 0 1.57087 -1.57079 -7.3e-05</pose>
          <geometry>
            <mesh>
              <scale>1 1 1</scale>
              <uri>model://icub/meshes/visual/icub_r_thigh.dae</uri>
            </mesh>
          </geometry>
        </visual>
        <self_collide>0</self_collide>
        <kinematic>0</kinematic>
      </link>
      <joint name='r_hip_yaw' type='revolute'>
        <child>r_upper_leg</child>
        <parent>r_hip_3</parent>
        <axis>
          <xyz>-7e-06 4e-06 -1</xyz>
          <limit>
            <lower>-1.37881</lower>
            <upper>1.37881</upper>
            <effort>40</effort>
            <velocity>100</velocity>
          </limit>
          <dynamics>
            <damping>1</damping>
            <friction>0</friction>
            <spring_reference>0</spring_reference>
            <spring_stiffness>0</spring_stiffness>
          </dynamics>
          <use_parent_model_frame>1</use_parent_model_frame>
        </axis>
      </joint>
      <link name='r_lower_leg'>
        <pose frame=''>-2e-06 0.068101 -0.3435 1.89254 -1.57078 -0.321751</pose>
        <inertial>
          <pose frame=''>-0.1071 0.00182 -0.00211 0 -0 0</pose>
          <mass>1.264</mass>
          <inertia>
            <ixx>0.01</ixx>
            <ixy>5.42101e-20</ixy>
            <ixz>-5.42101e-20</ixz>
            <iyy>0.01</iyy>
            <iyz>8.47033e-22</iyz>
            <izz>0.01</izz>
          </inertia>
        </inertial>
        <collision name='r_lower_leg_collision'>
          <pose frame=''>0 0 -0 3.14159 -0 1.5708</pose>
          <geometry>
            <mesh>
              <scale>1 1 1</scale>
              <uri>model://icub/meshes/collision/icub_simple_collision_r_shank.dae</uri>
            </mesh>
          </geometry>
          <max_contacts>10</max_contacts>
          <surface>
            <contact>
              <ode/>
            </contact>
            <bounce/>
            <friction>
              <torsional>
                <ode/>
              </torsional>
              <ode/>
            </friction>
          </surface>
        </collision>
        <visual name='r_lower_leg_visual'>
          <pose frame=''>0 0 -0 3.14159 -0 1.5708</pose>
          <geometry>
            <mesh>
              <scale>1 1 1</scale>
              <uri>model://icub/meshes/visual/icub_r_shank.dae</uri>
            </mesh>
          </geometry>
        </visual>
        <self_collide>0</self_collide>
        <kinematic>0</kinematic>
      </link>
      <joint name='r_knee' type='revolute'>
        <child>r_lower_leg</child>
        <parent>r_upper_leg</parent>
        <axis>
          <xyz>3e-06 1 4e-06</xyz>
          <limit>
            <lower>-2.18166</lower>
            <upper>0.401426</upper>
            <effort>30</effort>
            <velocity>100</velocity>
          </limit>
          <dynamics>
            <damping>1</damping>
            <friction>0</friction>
            <spring_reference>0</spring_reference>
            <spring_stiffness>0</spring_stiffness>
          </dynamics>
          <use_parent_model_frame>1</use_parent_model_frame>
        </axis>
      </joint>
      <link name='r_ankle_1'>
        <pose frame=''>-4e-06 0.068102 -0.5565 -2.81984 -1.57078 -0.321751</pose>
        <inertial>
          <pose frame=''>-0.0054 0.00163 -0.0172 0 -0 0</pose>
          <mass>0.746</mass>
          <inertia>
            <ixx>0.01</ixx>
            <ixy>-1.69407e-21</ixy>
            <ixz>1.35525e-20</ixz>
            <iyy>0.01</iyy>
            <iyz>3.38813e-21</iyz>
            <izz>0.01</izz>
          </inertia>
        </inertial>
        <collision name='r_ankle_1_collision'>
          <pose frame=''>0 -0 -0 -1.5708 -0 0</pose>
          <geometry>
            <mesh>
              <scale>1 1 1</scale>
              <uri>model://icub/meshes/collision/icub_simple_collision_r_ankle_1.dae</uri>
            </mesh>
          </geometry>
          <max_contacts>10</max_contacts>
          <surface>
            <contact>
              <ode/>
            </contact>
            <bounce/>
            <friction>
              <torsional>
                <ode/>
              </torsional>
              <ode/>
            </friction>
          </surface>
        </collision>
        <visual name='r_ankle_1_visual'>
          <pose frame=''>0 -0 -0 -1.5708 -0 0</pose>
          <geometry>
            <mesh>
              <scale>1 1 1</scale>
              <uri>model://icub/meshes/visual/icub_r_ankle_1.dae</uri>
            </mesh>
          </geometry>
        </visual>
        <self_collide>0</self_collide>
        <kinematic>0</kinematic>
      </link>
      <joint name='r_ankle_pitch' type='revolute'>
        <child>r_ankle_1</child>
        <parent>r_lower_leg</parent>
        <axis>
          <xyz>1e-06 -1 -4e-06</xyz>
          <limit>
            <lower>-0.733038</lower>
            <upper>0.366519</upper>
            <effort>24</effort>
            <velocity>100</velocity>
          </limit>
          <dynamics>
            <damping>1</damping>
            <friction>0</friction>
            <spring_reference>0</spring_reference>
            <spring_stiffness>0</spring_stiffness>
          </dynamics>
          <use_parent_model_frame>1</use_parent_model_frame>
        </axis>
      </joint>
      <link name='r_ankle_2'>
        <pose frame=''>-4e-06 0.068102 -0.5565 3.14159 -1.4e-05 -3.14159</pose>
        <inertial>
          <pose frame=''>0 0 0.037 0 -0 0</pose>
          <mass>0.2675</mass>
          <inertia>
            <ixx>0.01</ixx>
            <ixy>0</ixy>
            <ixz>0</ixz>
            <iyy>0.01</iyy>
            <iyz>0</iyz>
            <izz>0.01</izz>
          </inertia>
        </inertial>
        <self_collide>0</self_collide>
        <kinematic>0</kinematic>
      </link>
      <joint name='r_ankle_roll' type='revolute'>
        <child>r_ankle_2</child>
        <parent>r_ankle_1</parent>
        <axis>
          <xyz>1 3e-06 -1.4e-05</xyz>
          <limit>
            <lower>-0.418879</lower>
            <upper>0.418879</upper>
            <effort>11</effort>
            <velocity>100</velocity>
          </limit>
          <dynamics>
            <damping>1</damping>
            <friction>0</friction>
            <spring_reference>0</spring_reference>
            <spring_stiffness>0</spring_stiffness>
          </dynamics>
          <use_parent_model_frame>1</use_parent_model_frame>
        </axis>
      </joint>
      <link name='r_foot'>
        <pose frame=''>-5e-06 0.068102 -0.5935 3.14159 -1.4e-05 -3.14159</pose>
        <inertial>
          <pose frame=''>0.024069 0.000614 -0.028415 0 -0 0</pose>
          <mass>0.5935</mass>
          <inertia>
            <ixx>0.01</ixx>
            <ixy>4.51893e-06</ixy>
            <ixz>0.000567784</ixz>
            <iyy>0.01</iyy>
            <iyz>6.62535e-07</iyz>
            <izz>0.01</izz>
          </inertia>
        </inertial>
        <collision name='r_foot_collision'>
          <pose frame=''>0.03 0 -0.01 0 -0 0</pose>
          <geometry>
            <box>
              <size>0.15 0.07 0.03</size>
            </box>
          </geometry>
          <max_contacts>4</max_contacts>
          <surface>
            <contact>
              <ode>
                <soft_erp>0.2</soft_erp>
                <soft_cfm>0</soft_cfm>
                <kp>1.8e+07</kp>
                <kd>100</kd>
                <max_vel>100</max_vel>
                <min_depth>0.0001</min_depth>
              </ode>
            </contact>
            <friction>
              <ode>
                <mu>1</mu>
                <mu2>1</mu2>
                <fdir1>0 0 0</fdir1>
                <slip1>0</slip1>
                <slip2>0</slip2>
              </ode>
              <torsional>
                <ode/>
              </torsional>
            </friction>
            <bounce>
              <restitution_coefficient>0</restitution_coefficient>
              <threshold>100000</threshold>
            </bounce>
          </surface>
        </collision>
        <visual name='r_foot_visual'>
          <pose frame=''>0 0 -0.037 -2.81983 1.57079 0.321763</pose>
          <geometry>
            <mesh>
              <scale>1 1 1</scale>
              <uri>model://icub/meshes/visual/icub_r_foot.dae</uri>
            </mesh>
          </geometry>
        </visual>
        <self_collide>0</self_collide>
        <kinematic>0</kinematic>
      </link>
      <joint name='r_foot_ft_sensor' type='revolute'>
        <child>r_foot</child>
        <parent>r_ankle_2</parent>
        <axis>
          <xyz>0 0 0</xyz>
          <limit>
            <lower>0</lower>
            <upper>0</upper>
            <effort>0</effort>
            <velocity>0</velocity>
          </limit>
          <dynamics>
            <spring_reference>0</spring_reference>
            <spring_stiffness>0</spring_stiffness>
          </dynamics>
          <use_parent_model_frame>1</use_parent_model_frame>
        </axis>
        <sensor name='right_foot_ft' type='force_torque'>
          <always_on>1</always_on>
          <update_rate>100</update_rate>
          <pose frame=''>0 0 0 0 -0 0</pose>
          <plugin name='right_foot_ft_plugin' filename='libgazebo_yarp_forcetorque.so'>
            <yarpConfigurationFile>model://icub/conf/FT/gazebo_icub_right_foot_ft.ini</yarpConfigurationFile>
          </plugin>
        </sensor>
      </joint>
      <link name='torso_1'>
        <pose frame=''>0 0 0 3.14159 -1.57079 -3e-06</pose>
        <inertial>
          <pose frame=''>0 0 0 0 -0 0</pose>
          <mass>0.1</mass>
          <inertia>
            <ixx>0.01</ixx>
            <ixy>-4.263e-05</ixy>
            <ixz>-3.889e-08</ixz>
            <iyy>0.01</iyy>
            <iyz>0</iyz>
            <izz>0.01</izz>
          </inertia>
        </inertial>
        <collision name='torso_1_collision'>
          <pose frame=''>0 0 0 -1.5708 0 0</pose>
          <geometry>
            <mesh>
              <scale>1 1 1</scale>
              <uri>model://icub/meshes/collision/icub_simple_collision_lap_belt_1.dae</uri>
            </mesh>
          </geometry>
          <max_contacts>10</max_contacts>
          <surface>
            <contact>
              <ode/>
            </contact>
            <bounce/>
            <friction>
              <torsional>
                <ode/>
              </torsional>
              <ode/>
            </friction>
          </surface>
        </collision>
        <visual name='torso_1_visual'>
          <pose frame=''>0 0 0 -1.5708 0 0</pose>
          <geometry>
            <mesh>
              <scale>1 1 1</scale>
              <uri>model://icub/meshes/visual/icub_lap_belt_1.dae</uri>
            </mesh>
          </geometry>
        </visual>
        <self_collide>0</self_collide>
        <kinematic>0</kinematic>
      </link>
      <joint name='torso_pitch' type='revolute'>
        <child>torso_1</child>
        <parent>root_link</parent>
        <axis>
          <xyz>-3e-06 -1 0</xyz>
          <limit>
            <lower>-0.383972</lower>
            <upper>1.46608</upper>
            <effort>36</effort>
            <velocity>100</velocity>
          </limit>
          <dynamics>
            <damping>1</damping>
            <friction>0</friction>
            <spring_reference>0</spring_reference>
            <spring_stiffness>0</spring_stiffness>
          </dynamics>
          <use_parent_model_frame>1</use_parent_model_frame>
        </axis>
      </joint>
      <link name='torso_2'>
        <pose frame=''>0 -0 0.032 -3.14159 4e-06 1.57079</pose>
        <inertial>
          <pose frame=''>0 0 0 0 -0 0</pose>
          <mass>0.1</mass>
          <inertia>
            <ixx>0.01</ixx>
            <ixy>-1.923e-06</ixy>
            <ixz>5.095e-05</ixz>
            <iyy>0.01</iyy>
            <iyz>-3.849e-07</iyz>
            <izz>0.01</izz>
          </inertia>
        </inertial>
        <self_collide>0</self_collide>
        <kinematic>0</kinematic>
      </link>
      <joint name='torso_roll' type='revolute'>
        <child>torso_2</child>
        <parent>torso_1</parent>
        <axis>
          <xyz>1 -3e-06 -7e-06</xyz>
          <limit>
            <lower>-0.680678</lower>
            <upper>0.680678</upper>
            <effort>80</effort>
            <velocity>100</velocity>
          </limit>
          <dynamics>
            <damping>1</damping>
            <friction>0</friction>
            <spring_reference>0</spring_reference>
            <spring_stiffness>0</spring_stiffness>
          </dynamics>
          <use_parent_model_frame>1</use_parent_model_frame>
        </axis>
      </joint>
      <link name='chest'>
        <pose frame=''>-0.0055 0 0.032 1.5708 -7e-06 -3.14159</pose>
        <inertial>
          <pose frame=''>0.002229 0.075 -0 0 -0 0</pose>
          <mass>4.81</mass>
          <inertia>
            <ixx>0.07472</ixx>
            <ixy>-3.6e-06</ixy>
            <ixz>-4.705e-05</ixz>
            <iyy>0.08145</iyy>
            <iyz>0.004567</iyz>
            <izz>0.01306</izz>
          </inertia>
        </inertial>
        <collision name='chest_collision'>
          <pose frame=''>-0.0055 -0 -0 -1.10717 -1.57079 2.67798</pose>
          <geometry>
            <mesh>
              <scale>1 1 1</scale>
              <uri>model://icub/meshes/collision/icub_simple_collision_chest.dae</uri>
            </mesh>
          </geometry>
          <max_contacts>10</max_contacts>
          <surface>
            <contact>
              <ode/>
            </contact>
            <bounce/>
            <friction>
              <torsional>
                <ode/>
              </torsional>
              <ode/>
            </friction>
          </surface>
        </collision>
        <visual name='chest_visual'>
          <pose frame=''>-0.0055 -0 -0 -1.10717 -1.57079 2.67798</pose>
          <geometry>
            <mesh>
              <scale>1 1 1</scale>
              <uri>model://icub/meshes/visual/icub_chest.dae</uri>
            </mesh>
          </geometry>
        </visual>
        <self_collide>0</self_collide>
        <kinematic>0</kinematic>
      </link>
      <joint name='torso_yaw' type='revolute'>
        <child>chest</child>
        <parent>torso_2</parent>
        <axis>
          <xyz>-7e-06 0 -1</xyz>
          <limit>
            <lower>-1.02974</lower>
            <upper>1.02974</upper>
            <effort>80</effort>
            <velocity>100</velocity>
          </limit>
          <dynamics>
            <damping>1</damping>
            <friction>0</friction>
            <spring_reference>0</spring_reference>
            <spring_stiffness>0</spring_stiffness>
          </dynamics>
          <use_parent_model_frame>1</use_parent_model_frame>
        </axis>
      </joint>
      <link name='l_shoulder_1'>
        <pose frame=''>-0.010749 -0.11026 0.1753 -0.261794 -1.57079 -1e-06</pose>
        <inertial>
          <pose frame=''>-5e-06 0.0187 -0.00119 0 -0 0</pose>
          <mass>0.189</mass>
          <inertia>
            <ixx>0.01</ixx>
            <ixy>9e-09</ixy>
            <ixz>0</ixz>
            <iyy>0.01</iyy>
            <iyz>-1.7e-08</iyz>
            <izz>0.01</izz>
          </inertia>
        </inertial>
        <collision name='l_shoulder_1_collision'>
          <pose frame=''>0 0.109285 -0.005211 -0.301063 1.57079 -1.87186</pose>
          <geometry>
            <mesh>
              <scale>1 1 1</scale>
              <uri>model://icub/meshes/collision/icub_simple_collision_l_shoulder_1.dae</uri>
            </mesh>
          </geometry>
          <max_contacts>10</max_contacts>
          <surface>
            <contact>
              <ode/>
            </contact>
            <bounce/>
            <friction>
              <torsional>
                <ode/>
              </torsional>
              <ode/>
            </friction>
          </surface>
        </collision>
        <visual name='l_shoulder_1_visual'>
          <pose frame=''>0 0.109285 -0.005211 -0.301063 1.57079 -1.87186</pose>
          <geometry>
            <mesh>
              <scale>1 1 1</scale>
              <uri>model://icub/meshes/visual/icub_l_shoulder_1.dae</uri>
            </mesh>
          </geometry>
        </visual>
        <self_collide>0</self_collide>
        <kinematic>0</kinematic>
      </link>
      <joint name='l_shoulder_pitch' type='revolute'>
        <child>l_shoulder_1</child>
        <parent>chest</parent>
        <axis>
          <xyz>-0.258815 -0.965927 3e-06</xyz>
          <limit>
            <lower>-1.65806</lower>
            <upper>0.0872665</upper>
            <effort>84</effort>
            <velocity>100</velocity>
          </limit>
          <dynamics>
            <damping>1</damping>
            <friction>0</friction>
            <spring_reference>0</spring_reference>
            <spring_stiffness>0</spring_stiffness>
          </dynamics>
          <use_parent_model_frame>1</use_parent_model_frame>
        </axis>
      </joint>
      <link name='l_shoulder_2'>
        <pose frame=''>-0.010749 -0.11026 0.1753 3.14159 1e-06 -1.83259</pose>
        <inertial>
          <pose frame=''>9.4e-05 -0.00627 0.0166 0 -0 0</pose>
          <mass>0.179</mass>
          <inertia>
            <ixx>0.01</ixx>
            <ixy>4.66e-07</ixy>
            <ixz>3.65e-07</ixz>
            <iyy>0.01</iyy>
            <iyz>-2.0524e-05</iyz>
            <izz>0.01</izz>
          </inertia>
        </inertial>
        <collision name='l_shoulder_2_collision'>
          <pose frame=''>-0.001545 -0.005211 -0 -2.14033 1.57079 -0.569533</pose>
          <geometry>
            <mesh>
              <scale>1 1 1</scale>
              <uri>model://icub/meshes/collision/icub_simple_collision_l_shoulder_2.dae</uri>
            </mesh>
          </geometry>
          <max_contacts>10</max_contacts>
          <surface>
            <contact>
              <ode/>
            </contact>
            <bounce/>
            <friction>
              <torsional>
                <ode/>
              </torsional>
              <ode/>
            </friction>
          </surface>
        </collision>
        <visual name='l_shoulder_2_visual'>
          <pose frame=''>-0.001545 -0.005211 -0 -2.14033 1.57079 -0.569533</pose>
          <geometry>
            <mesh>
              <scale>1 1 1</scale>
              <uri>model://icub/meshes/visual/icub_l_shoulder_2.dae</uri>
            </mesh>
          </geometry>
        </visual>
        <self_collide>0</self_collide>
        <kinematic>0</kinematic>
      </link>
      <joint name='l_shoulder_roll' type='revolute'>
        <child>l_shoulder_2</child>
        <parent>l_shoulder_1</parent>
        <axis>
          <xyz>-0.965927 0.258815 7e-06</xyz>
          <limit>
            <lower>0</lower>
            <upper>2.80649</upper>
            <effort>84</effort>
            <velocity>100</velocity>
          </limit>
          <dynamics>
            <damping>1</damping>
            <friction>0</friction>
            <spring_reference>0</spring_reference>
            <spring_stiffness>0</spring_stiffness>
          </dynamics>
          <use_parent_model_frame>1</use_parent_model_frame>
        </axis>
      </joint>
      <link name='l_shoulder_3'>
        <pose frame=''>-0.010749 -0.11026 0.1753 3.14159 -7e-06 -3.14159</pose>
        <inertial>
          <pose frame=''>0.005594 9.8e-05 0.050135 0 -0 0</pose>
          <mass>0.156157</mass>
          <inertia>
            <ixx>0.01</ixx>
            <ixy>-5.662e-08</ixy>
            <ixz>-4.3618e-06</ixz>
            <iyy>0.01</iyy>
            <iyz>-7.42844e-07</iyz>
            <izz>0.01</izz>
          </inertia>
        </inertial>
        <self_collide>0</self_collide>
        <kinematic>0</kinematic>
      </link>
      <joint name='l_shoulder_yaw' type='revolute'>
        <child>l_shoulder_3</child>
        <parent>l_shoulder_2</parent>
        <axis>
          <xyz>-7e-06 3e-06 -1</xyz>
          <limit>
            <lower>-0.645772</lower>
            <upper>1.74533</upper>
            <effort>34</effort>
            <velocity>100</velocity>
          </limit>
          <dynamics>
            <damping>1</damping>
            <friction>0</friction>
            <spring_reference>0</spring_reference>
            <spring_stiffness>0</spring_stiffness>
          </dynamics>
          <use_parent_model_frame>1</use_parent_model_frame>
        </axis>
      </joint>
      <link name='l_upper_arm'>
        <pose frame=''>-0.025749 -0.11026 0.1073 3.14159 -7e-06 -3.14159</pose>
        <inertial>
          <pose frame=''>-0.000156 -9.9e-05 0.0298 0 -0 0</pose>
          <mass>0.727843</mass>
          <inertia>
            <ixx>0.01</ixx>
            <ixy>-1.08e-06</ixy>
            <ixz>-2.29e-06</ixz>
            <iyy>0.01</iyy>
            <iyz>3.57e-06</iyz>
            <izz>0.01</izz>
          </inertia>
        </inertial>
        <collision name='l_upper_arm_collision'>
          <pose frame=''>-0.020433 0.000144 -0.068 0 0 -1.309</pose>
          <geometry>
            <mesh>
              <scale>1 1 1</scale>
              <uri>model://icub/meshes/collision/icub_simple_collision_l_arm.dae</uri>
            </mesh>
          </geometry>
          <max_contacts>10</max_contacts>
          <surface>
            <contact>
              <ode/>
            </contact>
            <bounce/>
            <friction>
              <torsional>
                <ode/>
              </torsional>
              <ode/>
            </friction>
          </surface>
        </collision>
        <visual name='l_upper_arm_visual'>
          <pose frame=''>-0.020433 0.000144 -0.068 0 0 -1.309</pose>
          <geometry>
            <mesh>
              <scale>1 1 1</scale>
              <uri>model://icub/meshes/visual/icub_l_arm.dae</uri>
            </mesh>
          </geometry>
        </visual>
        <self_collide>0</self_collide>
        <kinematic>0</kinematic>
      </link>
      <joint name='l_arm_ft_sensor' type='revolute'>
        <child>l_upper_arm</child>
        <parent>l_shoulder_3</parent>
        <axis>
          <xyz>0 0 0</xyz>
          <limit>
            <lower>0</lower>
            <upper>0</upper>
            <effort>0</effort>
            <velocity>0</velocity>
          </limit>
          <dynamics>
            <spring_reference>0</spring_reference>
            <spring_stiffness>0</spring_stiffness>
          </dynamics>
          <use_parent_model_frame>1</use_parent_model_frame>
        </axis>
        <sensor name='left_arm_ft' type='force_torque'>
          <always_on>1</always_on>
          <update_rate>100</update_rate>
          <pose frame=''>0 0 0 0 -0 0</pose>
          <plugin name='left_arm_ft_plugin' filename='libgazebo_yarp_forcetorque.so'>
            <yarpConfigurationFile>model://icub/conf/FT/gazebo_icub_left_arm_ft.ini</yarpConfigurationFile>
          </plugin>
        </sensor>
      </joint>
      <link name='l_elbow_1'>
        <pose frame=''>-0.02575 -0.11026 0.02302 3.14159 -7e-06 -3.14159</pose>
        <inertial>
          <pose frame=''>-0.0013 0.00371 -0.00105 0 -0 0</pose>
          <mass>0.1</mass>
          <inertia>
            <ixx>0.01</ixx>
            <ixy>-5.15e-07</ixy>
            <ixz>-4.08e-07</ixz>
            <iyy>0.01</iyy>
            <iyz>-3.71e-07</iyz>
            <izz>0.01</izz>
          </inertia>
        </inertial>
        <self_collide>0</self_collide>
        <kinematic>0</kinematic>
      </link>
      <joint name='l_elbow' type='revolute'>
        <child>l_elbow_1</child>
        <parent>l_upper_arm</parent>
        <axis>
          <xyz>-1e-06 1 3e-06</xyz>
          <limit>
            <lower>0.0959931</lower>
            <upper>1.85005</upper>
            <effort>20</effort>
            <velocity>100</velocity>
          </limit>
          <dynamics>
            <damping>1</damping>
            <friction>0</friction>
            <spring_reference>0</spring_reference>
            <spring_stiffness>0</spring_stiffness>
          </dynamics>
          <use_parent_model_frame>1</use_parent_model_frame>
        </axis>
      </joint>
      <link name='l_forearm'>
        <pose frame=''>-0.01075 -0.11026 0.02302 -1.5708 3e-06 -1.57079</pose>
        <inertial>
          <pose frame=''>0.000347 0.066 0.00476 0 -0 0</pose>
          <mass>0.525</mass>
          <inertia>
            <ixx>0.01</ixx>
            <ixy>4.337e-06</ixy>
            <ixz>2.39e-07</ixz>
            <iyy>0.01</iyy>
            <iyz>1.9381e-05</iyz>
            <izz>0.01</izz>
          </inertia>
        </inertial>
        <collision name='l_forearm_collision'>
          <pose frame=''>-0.000144 -0 0.020433 -2.66395 1.57079 -1.09315</pose>
          <geometry>
            <mesh>
              <scale>1 1 1</scale>
              <uri>model://icub/meshes/collision/icub_simple_collision_l_forearm.dae</uri>
            </mesh>
          </geometry>
          <max_contacts>10</max_contacts>
          <surface>
            <contact>
              <ode/>
            </contact>
            <bounce/>
            <friction>
              <torsional>
                <ode/>
              </torsional>
              <ode/>
            </friction>
          </surface>
        </collision>
        <visual name='l_forearm_visual'>
          <pose frame=''>-0.000144 -0 0.020433 -2.66395 1.57079 -1.09315</pose>
          <geometry>
            <mesh>
              <scale>1 1 1</scale>
              <uri>model://icub/meshes/visual/icub_l_forearm.dae</uri>
            </mesh>
          </geometry>
        </visual>
        <self_collide>0</self_collide>
        <kinematic>0</kinematic>
      </link>
      <joint name='l_wrist_prosup' type='revolute'>
        <child>l_forearm</child>
        <parent>l_elbow_1</parent>
        <axis>
          <xyz>-3e-06 3e-06 -1</xyz>
          <limit>
            <lower>-0.872665</lower>
            <upper>0.872665</upper>
            <effort>0.45</effort>
            <velocity>100</velocity>
          </limit>
          <dynamics>
            <damping>1</damping>
            <friction>0</friction>
            <spring_reference>0</spring_reference>
            <spring_stiffness>0</spring_stiffness>
          </dynamics>
          <use_parent_model_frame>1</use_parent_model_frame>
        </axis>
      </joint>
      <link name='l_wrist_1'>
        <pose frame=''>-0.01075 -0.110259 -0.11428 -2.7153 1.57079 1.99709</pose>
        <inertial>
          <pose frame=''>0 0 0 0 -0 0</pose>
          <mass>0.1</mass>
          <inertia>
            <ixx>0.01</ixx>
            <ixy>0</ixy>
            <ixz>0</ixz>
            <iyy>0.01</iyy>
            <iyz>0</iyz>
            <izz>0.01</izz>
          </inertia>
        </inertial>
        <self_collide>0</self_collide>
        <kinematic>0</kinematic>
      </link>
      <joint name='l_wrist_pitch' type='revolute'>
        <child>l_wrist_1</child>
        <parent>l_forearm</parent>
        <axis>
          <xyz>1 1e-06 -3e-06</xyz>
          <limit>
            <lower>-1.13446</lower>
            <upper>0.174533</upper>
            <effort>0.65</effort>
            <velocity>100</velocity>
          </limit>
          <dynamics>
            <damping>1</damping>
            <friction>0</friction>
            <spring_reference>0</spring_reference>
            <spring_stiffness>0</spring_stiffness>
          </dynamics>
          <use_parent_model_frame>1</use_parent_model_frame>
        </axis>
      </joint>
      <link name='l_hand'>
        <pose frame=''>-0.01075 -0.110259 -0.11428 -2.7153 1.57079 1.99709</pose>
        <inertial>
          <pose frame=''>0.07023 -0.00805 -0.007 0 -0 0</pose>
          <mass>0.213</mass>
          <inertia>
            <ixx>0.01</ixx>
            <ixy>1.278e-05</ixy>
            <ixz>4.823e-06</ixz>
            <iyy>0.01</iyy>
            <iyz>-1.8188e-05</iyz>
            <izz>0.01</izz>
          </inertia>
        </inertial>
        <collision name='l_hand_collision'>
          <pose frame=''>-0 0.020433 -0.000144 0 -0 0</pose>
          <geometry>
            <mesh>
              <scale>1 1 1</scale>
              <uri>model://icub/meshes/collision/icub_simple_collision_l_hand.dae</uri>
            </mesh>
          </geometry>
          <max_contacts>10</max_contacts>
          <surface>
            <contact>
              <ode/>
            </contact>
            <bounce/>
            <friction>
              <torsional>
                <ode/>
              </torsional>
              <ode/>
            </friction>
          </surface>
        </collision>
        <visual name='l_hand_visual'>
          <pose frame=''>-0 0.020433 -0.000144 0 -0 0</pose>
          <geometry>
            <mesh>
              <scale>1 1 1</scale>
              <uri>model://icub/meshes/visual/icub_l_hand.dae</uri>
            </mesh>
          </geometry>
        </visual>
        <self_collide>0</self_collide>
        <kinematic>0</kinematic>
      </link>
      <joint name='l_wrist_yaw' type='revolute'>
        <child>l_hand</child>
        <parent>l_wrist_1</parent>
        <axis>
          <xyz>1e-06 -1 -6e-06</xyz>
          <limit>
            <lower>-0.436332</lower>
            <upper>0.436332</upper>
            <effort>0.65</effort>
            <velocity>100</velocity>
          </limit>
          <dynamics>
            <damping>1</damping>
            <friction>0</friction>
            <spring_reference>0</spring_reference>
            <spring_stiffness>0</spring_stiffness>
          </dynamics>
          <use_parent_model_frame>1</use_parent_model_frame>
        </axis>
      </joint>
      <link name='neck_1'>
        <pose frame=''>-0.007808 0 0.2253 6e-06 -1.57079 -1e-06</pose>
        <inertial>
          <pose frame=''>0 0 0 0 -0 0</pose>
          <mass>0.1</mass>
          <inertia>
            <ixx>0.01</ixx>
            <ixy>0</ixy>
            <ixz>0</ixz>
            <iyy>0.01</iyy>
            <iyz>0</iyz>
            <izz>0.01</izz>
          </inertia>
        </inertial>
        <collision name='neck_1_collision'>
          <pose frame=''>-0 0 -0.0055 3.14159 -1.57079 1.5708</pose>
          <geometry>
            <mesh>
              <scale>1 1 1</scale>
              <uri>model://icub/meshes/collision/icub_simple_collision_neck_1.dae</uri>
            </mesh>
          </geometry>
          <max_contacts>10</max_contacts>
          <surface>
            <contact>
              <ode/>
            </contact>
            <bounce/>
            <friction>
              <torsional>
                <ode/>
              </torsional>
              <ode/>
            </friction>
          </surface>
        </collision>
        <visual name='neck_1_visual'>
          <pose frame=''>-0 0 -0.0055 3.14159 -1.57079 1.5708</pose>
          <geometry>
            <mesh>
              <scale>1 1 1</scale>
              <uri>model://icub/meshes/visual/icub_neck_1.dae</uri>
            </mesh>
          </geometry>
        </visual>
        <self_collide>0</self_collide>
        <kinematic>0</kinematic>
      </link>
      <joint name='neck_pitch' type='revolute'>
        <child>neck_1</child>
        <parent>chest</parent>
        <axis>
          <xyz>-5e-06 1 0</xyz>
          <limit>
            <lower>-0.523599</lower>
            <upper>0.383972</upper>
            <effort>20</effort>
            <velocity>100</velocity>
          </limit>
          <dynamics>
            <damping>1</damping>
            <friction>0</friction>
            <spring_reference>0</spring_reference>
            <spring_stiffness>0</spring_stiffness>
          </dynamics>
          <use_parent_model_frame>1</use_parent_model_frame>
        </axis>
        <physics>
          <ode>
            <implicit_spring_damper>1</implicit_spring_damper>
            <cfm_damping>1</cfm_damping>
            <limit>
              <cfm>0</cfm>
              <erp>0.2</erp>
            </limit>
          </ode>
        </physics>
      </joint>
      <link name='neck_2'>
        <pose frame=''>-0.007808 0 0.2348 -1.5e-05 4e-06 -1.57079</pose>
        <inertial>
          <pose frame=''>0 0 0 0 -0 0</pose>
          <mass>0.1</mass>
          <inertia>
            <ixx>0.01</ixx>
            <ixy>0</ixy>
            <ixz>0</ixz>
            <iyy>0.01</iyy>
            <iyz>0</iyz>
            <izz>0.01</izz>
          </inertia>
        </inertial>
        <collision name='neck_2_collision'>
          <pose frame=''>-0 0.0055 0.0235 -3.14157 -1.57079 -1.57082</pose>
          <geometry>
            <mesh>
              <scale>1 1 1</scale>
              <uri>model://icub/meshes/collision/icub_simple_collision_neck_2.dae</uri>
            </mesh>
          </geometry>
          <max_contacts>10</max_contacts>
          <surface>
            <contact>
              <ode/>
            </contact>
            <bounce/>
            <friction>
              <torsional>
                <ode/>
              </torsional>
              <ode/>
            </friction>
          </surface>
        </collision>
        <visual name='neck_2_visual'>
          <pose frame=''>-0 0.0055 0.0235 -3.14157 -1.57079 -1.57082</pose>
          <geometry>
            <mesh>
              <scale>1 1 1</scale>
              <uri>model://icub/meshes/visual/icub_neck_2.dae</uri>
            </mesh>
          </geometry>
        </visual>
        <self_collide>0</self_collide>
        <kinematic>0</kinematic>
      </link>
      <joint name='neck_roll' type='revolute'>
        <child>neck_2</child>
        <parent>neck_1</parent>
        <axis>
          <xyz>-1 -5e-06 1.5e-05</xyz>
          <limit>
            <lower>-0.349066</lower>
            <upper>0.349066</upper>
            <effort>20</effort>
            <velocity>100</velocity>
          </limit>
          <dynamics>
            <damping>1</damping>
            <friction>0</friction>
            <spring_reference>0</spring_reference>
            <spring_stiffness>0</spring_stiffness>
          </dynamics>
          <use_parent_model_frame>1</use_parent_model_frame>
        </axis>
        <physics>
          <ode>
            <implicit_spring_damper>1</implicit_spring_damper>
            <cfm_damping>1</cfm_damping>
            <limit>
              <cfm>0</cfm>
              <erp>0.2</erp>
            </limit>
          </ode>
        </physics>
      </joint>
      <link name='head'>
        <pose frame=''>-0.007808 0 0.2348 -1.5708 1.5e-05 8e-06</pose>
        <inertial>
          <pose frame=''>0.0185 -0.1108 0 0 -0 0</pose>
          <mass>3</mass>
          <inertia>
            <ixx>0.01</ixx>
            <ixy>0</ixy>
            <ixz>0</ixz>
            <iyy>0.01</iyy>
            <iyz>0</iyz>
            <izz>0.01</izz>
          </inertia>
        </inertial>
        <collision name='head_collision'>
          <pose frame=''>0.0045 -0.0235 0 -1.32582 1.57079 -2.89662</pose>
          <geometry>
            <mesh>
              <scale>1 1 1</scale>
              <uri>model://icub/meshes/collision/icub_simple_collision_head.dae</uri>
            </mesh>
          </geometry>
          <max_contacts>10</max_contacts>
          <surface>
            <contact>
              <ode/>
            </contact>
            <bounce/>
            <friction>
              <torsional>
                <ode/>
              </torsional>
              <ode/>
            </friction>
          </surface>
        </collision>
        <visual name='head_visual'>
          <pose frame=''>0.0045 -0.0235 0 -2.89662 1.57079 -2.89662</pose>
          <geometry>
            <mesh>
              <scale>1 1 1</scale>
              <uri>model://icub/meshes/visual/icub_head_without_eyes.dae</uri>
            </mesh>
          </geometry>
        </visual>
        <sensor name='imu_sensor' type='imu'>
          <always_on>1</always_on>
          <update_rate>100</update_rate>
          <visualize>1</visualize>
          <imu>
            <angular_velocity/>
            <linear_acceleration/>
          </imu>
          <plugin name='iCub_yarp_gazebo_plugin_IMU' filename='libgazebo_yarp_imu.so'>
            <yarpConfigurationFile>model://icub/conf/gazebo_icub_inertial.ini</yarpConfigurationFile>
          </plugin>
          <pose frame=''>0.0185 -0.1108 0.0066 1.5708 -0 0</pose>
        </sensor>
        <self_collide>0</self_collide>
        <kinematic>0</kinematic>
      </link>
      <joint name='neck_yaw' type='revolute'>
        <child>head</child>
        <parent>neck_2</parent>
        <axis>
          <xyz>1.5e-05 0 1</xyz>
          <limit>
            <lower>-0.767945</lower>
            <upper>0.767945</upper>
            <effort>20</effort>
            <velocity>100</velocity>
          </limit>
          <dynamics>
            <damping>1</damping>
            <friction>0</friction>
            <spring_reference>0</spring_reference>
            <spring_stiffness>0</spring_stiffness>
          </dynamics>
          <use_parent_model_frame>1</use_parent_model_frame>
        </axis>
        <physics>
          <ode>
            <implicit_spring_damper>1</implicit_spring_damper>
            <cfm_damping>1</cfm_damping>
            <limit>
              <cfm>0</cfm>
              <erp>0.2</erp>
            </limit>
          </ode>
        </physics>
      </joint>
      <link name='eyes_tilt_link'>
        <pose frame=''>-0.06281 0 0.3408 1.57079 -0 0</pose>
        <inertial>
          <pose frame=''>0 0 0 0 -0 0</pose>
          <mass>0.01</mass>
          <inertia>
            <ixx>0.001</ixx>
            <ixy>0</ixy>
            <ixz>0</ixz>
            <iyy>0.001</iyy>
            <iyz>0</iyz>
            <izz>0.001</izz>
          </inertia>
        </inertial>
        <self_collide>0</self_collide>
        <kinematic>0</kinematic>
      </link>
      <link name='left_eye_link'>
        <pose frame=''>-0.06281 -0.034 0.3408 -3.14159 0 0</pose>
        <inertial>
          <pose frame=''>0 0 0 0 -0 0</pose>
          <mass>0.01</mass>
          <inertia>
            <ixx>0.001</ixx>
            <ixy>0</ixy>
            <ixz>0</ixz>
            <iyy>0.001</iyy>
            <iyz>0</iyz>
            <izz>0.001</izz>
          </inertia>
        </inertial>
        <visual name='left_eye_visual'>
          <pose frame=''>0.055 0.033 -0.14 0 -0 0</pose>
          <geometry>
            <mesh>
              <scale>1 1 1</scale>
              <uri>model://icub/meshes/visual/icub_eye.dae</uri>
            </mesh>
          </geometry>
        </visual>
        <self_collide>0</self_collide>
        <kinematic>0</kinematic>
      </link>
      <link name='right_eye_link'>
        <pose frame=''>-0.06281 0.034 0.3408 -3.14159 0 0</pose>
        <inertial>
          <pose frame=''>0 0 0 0 -0 0</pose>
          <mass>0.01</mass>
          <inertia>
            <ixx>0.001</ixx>
            <ixy>0</ixy>
            <ixz>0</ixz>
            <iyy>0.001</iyy>
            <iyz>0</iyz>
            <izz>0.001</izz>
          </inertia>
        </inertial>
        <visual name='right_eye_visual'>
          <pose frame=''>0.055 0.033 -0.14 0 -0 0</pose>
          <geometry>
            <mesh>
              <scale>1 1 1</scale>
              <uri>model://icub/meshes/visual/icub_eye.dae</uri>
            </mesh>
          </geometry>
        </visual>
        <self_collide>0</self_collide>
        <kinematic>0</kinematic>
      </link>
      <joint name='eyes_tilt' type='revolute'>
        <child>eyes_tilt_link</child>
        <parent>head</parent>
        <axis>
          <xyz>0 1 0</xyz>
          <limit>
            <lower>-1.5708</lower>
            <upper>1.5708</upper>
            <effort>84</effort>
            <velocity>100</velocity>
          </limit>
          <dynamics>
            <damping>1</damping>
            <friction>0</friction>
            <spring_reference>0</spring_reference>
            <spring_stiffness>0</spring_stiffness>
          </dynamics>
          <use_parent_model_frame>1</use_parent_model_frame>
        </axis>
        <physics>
          <ode>
            <implicit_spring_damper>1</implicit_spring_damper>
            <cfm_damping>1</cfm_damping>
            <limit>
              <cfm>0</cfm>
              <erp>0.2</erp>
            </limit>
          </ode>
        </physics>
      </joint>
      <joint name='left_eye' type='revolute'>
        <child>left_eye_link</child>
        <parent>eyes_tilt_link</parent>
        <axis>
          <xyz>0 0 1</xyz>
          <limit>
            <lower>-1.5708</lower>
            <upper>1.5708</upper>
            <effort>84</effort>
            <velocity>100</velocity>
          </limit>
          <dynamics>
            <damping>1</damping>
            <friction>0</friction>
            <spring_reference>0</spring_reference>
            <spring_stiffness>0</spring_stiffness>
          </dynamics>
          <use_parent_model_frame>1</use_parent_model_frame>
        </axis>
        <physics>
          <ode>
            <implicit_spring_damper>1</implicit_spring_damper>
            <cfm_damping>1</cfm_damping>
            <limit>
              <cfm>0</cfm>
              <erp>0.2</erp>
            </limit>
          </ode>
        </physics>
      </joint>
      <joint name='right_eye' type='revolute'>
        <child>right_eye_link</child>
        <parent>eyes_tilt_link</parent>
        <axis>
          <xyz>0 0 1</xyz>
          <limit>
            <lower>-1.5708</lower>
            <upper>1.5708</upper>
            <effort>84</effort>
            <velocity>100</velocity>
          </limit>
          <dynamics>
            <damping>1</damping>
            <friction>0</friction>
            <spring_reference>0</spring_reference>
            <spring_stiffness>0</spring_stiffness>
          </dynamics>
          <use_parent_model_frame>1</use_parent_model_frame>
        </axis>
        <physics>
          <ode>
            <implicit_spring_damper>1</implicit_spring_damper>
            <cfm_damping>1</cfm_damping>
            <limit>
              <cfm>0</cfm>
              <erp>0.2</erp>
            </limit>
          </ode>
        </physics>
      </joint>
      <link name='r_shoulder_1'>
        <pose frame=''>-0.010749 0.11026 0.1753 -2.87979 -1.57079 -1e-06</pose>
        <inertial>
          <pose frame=''>5e-06 0.0187 0.00119 0 -0 0</pose>
          <mass>0.189</mass>
          <inertia>
            <ixx>0.01</ixx>
            <ixy>2.1e-08</ixy>
            <ixz>-1e-09</ixz>
            <iyy>0.01</iyy>
            <iyz>4.22e-06</iyz>
            <izz>0.01</izz>
          </inertia>
        </inertial>
        <collision name='r_shoulder_1_collision'>
          <pose frame=''>-0 0.109285 0.005211 3.06003 1.57079 -1.65235</pose>
          <geometry>
            <mesh>
              <scale>1 1 1</scale>
              <uri>model://icub/meshes/collision/icub_simple_collision_r_shoulder_1.dae</uri>
            </mesh>
          </geometry>
          <max_contacts>10</max_contacts>
          <surface>
            <contact>
              <ode/>
            </contact>
            <bounce/>
            <friction>
              <torsional>
                <ode/>
              </torsional>
              <ode/>
            </friction>
          </surface>
        </collision>
        <visual name='r_shoulder_1_visual'>
          <pose frame=''>-0 0.109285 0.005211 3.06003 1.57079 -1.65235</pose>
          <geometry>
            <mesh>
              <scale>1 1 1</scale>
              <uri>model://icub/meshes/visual/icub_r_shoulder_1.dae</uri>
            </mesh>
          </geometry>
        </visual>
        <self_collide>0</self_collide>
        <kinematic>0</kinematic>
      </link>
      <joint name='r_shoulder_pitch' type='revolute'>
        <child>r_shoulder_1</child>
        <parent>chest</parent>
        <axis>
          <xyz>0.258817 -0.965926 -3e-06</xyz>
          <limit>
            <lower>-1.65806</lower>
            <upper>0.0872665</upper>
            <effort>84</effort>
            <velocity>100</velocity>
          </limit>
          <dynamics>
            <damping>1</damping>
            <friction>0</friction>
            <spring_reference>0</spring_reference>
            <spring_stiffness>0</spring_stiffness>
          </dynamics>
          <use_parent_model_frame>1</use_parent_model_frame>
        </axis>
      </joint>
      <link name='r_shoulder_2'>
        <pose frame=''>-0.010749 0.11026 0.1753 7e-06 1e-06 1.83259</pose>
        <inertial>
          <pose frame=''>-9.4e-05 -0.00627 -0.0166 0 -0 0</pose>
          <mass>0.179</mass>
          <inertia>
            <ixx>0.01</ixx>
            <ixy>-4.53e-07</ixy>
            <ixz>2.03e-07</ixz>
            <iyy>0.01</iyy>
            <iyz>2.07e-05</iyz>
            <izz>0.01</izz>
          </inertia>
        </inertial>
        <collision name='r_shoulder_2_collision'>
          <pose frame=''>-0.001545 -0.005211 -0 -1.00125 -1.57079 2.57205</pose>
          <geometry>
            <mesh>
              <scale>1 1 1</scale>
              <uri>model://icub/meshes/collision/icub_simple_collision_r_shoulder_2.dae</uri>
            </mesh>
          </geometry>
          <max_contacts>10</max_contacts>
          <surface>
            <contact>
              <ode/>
            </contact>
            <bounce/>
            <friction>
              <torsional>
                <ode/>
              </torsional>
              <ode/>
            </friction>
          </surface>
        </collision>
        <visual name='r_shoulder_2_visual'>
          <pose frame=''>-0.001545 -0.005211 -0 -1.00125 -1.57079 2.57205</pose>
          <geometry>
            <mesh>
              <scale>1 1 1</scale>
              <uri>model://icub/meshes/visual/icub_r_shoulder_2.dae</uri>
            </mesh>
          </geometry>
        </visual>
        <self_collide>0</self_collide>
        <kinematic>0</kinematic>
      </link>
      <joint name='r_shoulder_roll' type='revolute'>
        <child>r_shoulder_2</child>
        <parent>r_shoulder_1</parent>
        <axis>
          <xyz>0.965926 0.258817 -7e-06</xyz>
          <limit>
            <lower>0</lower>
            <upper>2.80649</upper>
            <effort>84</effort>
            <velocity>100</velocity>
          </limit>
          <dynamics>
            <damping>1</damping>
            <friction>0</friction>
            <spring_reference>0</spring_reference>
            <spring_stiffness>0</spring_stiffness>
          </dynamics>
          <use_parent_model_frame>1</use_parent_model_frame>
        </axis>
      </joint>
      <link name='r_shoulder_3'>
        <pose frame=''>-0.010749 0.11026 0.1753 3.14159 -7e-06 -3.14159</pose>
        <inertial>
          <pose frame=''>0.005539 -2.5e-05 0.04939 0 -0 0</pose>
          <mass>0.155</mass>
          <inertia>
            <ixx>0.01</ixx>
            <ixy>3.56977e-07</ixy>
            <ixz>-3.95372e-06</ixz>
            <iyy>0.01</iyy>
            <iyz>-6.5128e-06</iyz>
            <izz>0.01</izz>
          </inertia>
        </inertial>
        <self_collide>0</self_collide>
        <kinematic>0</kinematic>
      </link>
      <joint name='r_shoulder_yaw' type='revolute'>
        <child>r_shoulder_3</child>
        <parent>r_shoulder_2</parent>
        <axis>
          <xyz>7e-06 0 1</xyz>
          <limit>
            <lower>-0.645772</lower>
            <upper>1.74533</upper>
            <effort>34</effort>
            <velocity>100</velocity>
          </limit>
          <dynamics>
            <damping>1</damping>
            <friction>0</friction>
            <spring_reference>0</spring_reference>
            <spring_stiffness>0</spring_stiffness>
          </dynamics>
          <use_parent_model_frame>1</use_parent_model_frame>
        </axis>
      </joint>
      <link name='r_upper_arm'>
        <pose frame=''>-0.025749 0.11026 0.1073 3.14159 -7e-06 -3.14159</pose>
        <inertial>
          <pose frame=''>-0.000159 8.3e-05 0.029883 0 -0 0</pose>
          <mass>0.729</mass>
          <inertia>
            <ixx>0.01</ixx>
            <ixy>-1.08e-06</ixy>
            <ixz>-2.29e-06</ixz>
            <iyy>0.01</iyy>
            <iyz>3.57e-06</iyz>
            <izz>0.01</izz>
          </inertia>
        </inertial>
        <collision name='r_upper_arm_collision'>
          <pose frame=''>-0.020433 -0.000144 -0.068 -3.14159 -0 1.309</pose>
          <geometry>
            <mesh>
              <scale>1 1 1</scale>
              <uri>model://icub/meshes/collision/icub_simple_collision_r_arm.dae</uri>
            </mesh>
          </geometry>
          <max_contacts>10</max_contacts>
          <surface>
            <contact>
              <ode/>
            </contact>
            <bounce/>
            <friction>
              <torsional>
                <ode/>
              </torsional>
              <ode/>
            </friction>
          </surface>
        </collision>
        <visual name='r_upper_arm_visual'>
          <pose frame=''>-0.020433 -0.000144 -0.068 -3.14159 -0 1.309</pose>
          <geometry>
            <mesh>
              <scale>1 1 1</scale>
              <uri>model://icub/meshes/visual/icub_r_arm.dae</uri>
            </mesh>
          </geometry>
        </visual>
        <self_collide>0</self_collide>
        <kinematic>0</kinematic>
      </link>
      <joint name='r_arm_ft_sensor' type='revolute'>
        <child>r_upper_arm</child>
        <parent>r_shoulder_3</parent>
        <axis>
          <xyz>0 0 0</xyz>
          <limit>
            <lower>0</lower>
            <upper>0</upper>
            <effort>0</effort>
            <velocity>0</velocity>
          </limit>
          <dynamics>
            <spring_reference>0</spring_reference>
            <spring_stiffness>0</spring_stiffness>
          </dynamics>
          <use_parent_model_frame>1</use_parent_model_frame>
        </axis>
        <sensor name='right_arm_ft' type='force_torque'>
          <always_on>1</always_on>
          <update_rate>100</update_rate>
          <pose frame=''>0 0 0 0 -0 0</pose>
          <plugin name='right_arm_ft_plugin' filename='libgazebo_yarp_forcetorque.so'>
            <yarpConfigurationFile>model://icub/conf/FT/gazebo_icub_right_arm_ft.ini</yarpConfigurationFile>
          </plugin>
        </sensor>
      </joint>
      <link name='r_elbow_1'>
        <pose frame=''>-0.02575 0.11026 0.02302 -3e-06 7e-06 4e-06</pose>
        <inertial>
          <pose frame=''>0.0013 -0.00371 0.00105 0 -0 0</pose>
          <mass>0.1</mass>
          <inertia>
            <ixx>0.01</ixx>
            <ixy>-5.02e-07</ixy>
            <ixz>-3.99e-07</ixz>
            <iyy>0.01</iyy>
            <iyz>-3.71e-07</iyz>
            <izz>0.01</izz>
          </inertia>
        </inertial>
        <self_collide>0</self_collide>
        <kinematic>0</kinematic>
      </link>
      <joint name='r_elbow' type='revolute'>
        <child>r_elbow_1</child>
        <parent>r_upper_arm</parent>
        <axis>
          <xyz>-4e-06 1 -3e-06</xyz>
          <limit>
            <lower>0.0959931</lower>
            <upper>1.85005</upper>
            <effort>20</effort>
            <velocity>100</velocity>
          </limit>
          <dynamics>
            <damping>1</damping>
            <friction>0</friction>
            <spring_reference>0</spring_reference>
            <spring_stiffness>0</spring_stiffness>
          </dynamics>
          <use_parent_model_frame>1</use_parent_model_frame>
        </axis>
      </joint>
      <link name='r_forearm'>
        <pose frame=''>-0.01075 0.11026 0.02302 1.57079 -3e-06 -1.5708</pose>
        <inertial>
          <pose frame=''>-0.000347 -0.066 -0.00476 0 -0 0</pose>
          <mass>0.525</mass>
          <inertia>
            <ixx>0.01</ixx>
            <ixy>5.66e-06</ixy>
            <ixz>1.4e-06</ixz>
            <iyy>0.01</iyy>
            <iyz>1.82e-05</iyz>
            <izz>0.01</izz>
          </inertia>
        </inertial>
        <collision name='r_forearm_collision'>
          <pose frame=''>0.000144 -0 -0.020433 -1.74165 1.57079 -0.170863</pose>
          <geometry>
            <mesh>
              <scale>1 1 1</scale>
              <uri>model://icub/meshes/collision/icub_simple_collision_r_forearm.dae</uri>
            </mesh>
          </geometry>
          <max_contacts>10</max_contacts>
          <surface>
            <contact>
              <ode/>
            </contact>
            <bounce/>
            <friction>
              <torsional>
                <ode/>
              </torsional>
              <ode/>
            </friction>
          </surface>
        </collision>
        <visual name='r_forearm_visual'>
          <pose frame=''>0.000144 -0 -0.020433 -1.74165 1.57079 -0.170863</pose>
          <geometry>
            <mesh>
              <scale>1 1 1</scale>
              <uri>model://icub/meshes/visual/icub_r_forearm.dae</uri>
            </mesh>
          </geometry>
        </visual>
        <self_collide>0</self_collide>
        <kinematic>0</kinematic>
      </link>
      <joint name='r_wrist_prosup' type='revolute'>
        <child>r_forearm</child>
        <parent>r_elbow_1</parent>
        <axis>
          <xyz>3e-06 3e-06 1</xyz>
          <limit>
            <lower>-0.872665</lower>
            <upper>0.872665</upper>
            <effort>0.45</effort>
            <velocity>100</velocity>
          </limit>
          <dynamics>
            <damping>1</damping>
            <friction>0</friction>
            <spring_reference>0</spring_reference>
            <spring_stiffness>0</spring_stiffness>
          </dynamics>
          <use_parent_model_frame>1</use_parent_model_frame>
        </axis>
      </joint>
      <link name='r_wrist_1'>
        <pose frame=''>-0.01075 0.11026 -0.11428 0.426292 -1.57079 1.14451</pose>
        <inertial>
          <pose frame=''>0 0 0 0 -0 0</pose>
          <mass>0.1</mass>
          <inertia>
            <ixx>0.01</ixx>
            <ixy>0</ixy>
            <ixz>0</ixz>
            <iyy>0.01</iyy>
            <iyz>0</iyz>
            <izz>0.01</izz>
          </inertia>
        </inertial>
        <self_collide>0</self_collide>
        <kinematic>0</kinematic>
      </link>
      <joint name='r_wrist_pitch' type='revolute'>
        <child>r_wrist_1</child>
        <parent>r_forearm</parent>
        <axis>
          <xyz>-1 -4e-06 3e-06</xyz>
          <limit>
            <lower>-1.13446</lower>
            <upper>0.174533</upper>
            <effort>0.65</effort>
            <velocity>100</velocity>
          </limit>
          <dynamics>
            <damping>1</damping>
            <friction>0</friction>
            <spring_reference>0</spring_reference>
            <spring_stiffness>0</spring_stiffness>
          </dynamics>
          <use_parent_model_frame>1</use_parent_model_frame>
        </axis>
      </joint>
      <link name='r_hand'>
        <pose frame=''>-0.01075 0.11026 -0.11428 -0.720145 1.57079 -2.29094</pose>
        <inertial>
          <pose frame=''>0.07023 -0.00805 0.007 0 -0 0</pose>
          <mass>0.213</mass>
          <inertia>
            <ixx>0.01</ixx>
            <ixy>1.26e-05</ixy>
            <ixz>-6.08e-06</ixz>
            <iyy>0.01</iyy>
            <iyz>1.76e-05</iyz>
            <izz>0.01</izz>
          </inertia>
        </inertial>
        <collision name='r_hand_collision'>
          <pose frame=''>0 0.020433 0.000144 0 0 -3.14159</pose>
          <geometry>
            <mesh>
              <scale>1 1 1</scale>
              <uri>model://icub/meshes/collision/icub_simple_collision_r_hand.dae</uri>
            </mesh>
          </geometry>
          <max_contacts>10</max_contacts>
          <surface>
            <contact>
              <ode/>
            </contact>
            <bounce/>
            <friction>
              <torsional>
                <ode/>
              </torsional>
              <ode/>
            </friction>
          </surface>
        </collision>
        <visual name='r_hand_visual'>
          <pose frame=''>0 0.020433 0.000144 0 0 -3.14159</pose>
          <geometry>
            <mesh>
              <scale>1 1 1</scale>
              <uri>model://icub/meshes/visual/icub_r_hand.dae</uri>
            </mesh>
          </geometry>
        </visual>
        <self_collide>0</self_collide>
        <kinematic>0</kinematic>
      </link>
      <joint name='r_wrist_yaw' type='revolute'>
        <child>r_hand</child>
        <parent>r_wrist_1</parent>
        <axis>
          <xyz>4e-06 -1 6e-06</xyz>
          <limit>
            <lower>-0.436332</lower>
            <upper>0.436332</upper>
            <effort>0.65</effort>
            <velocity>100</velocity>
          </limit>
          <dynamics>
            <damping>1</damping>
            <friction>0</friction>
            <spring_reference>0</spring_reference>
            <spring_stiffness>0</spring_stiffness>
          </dynamics>
          <use_parent_model_frame>1</use_parent_model_frame>
        </axis>
      </joint>
      <plugin name='controlboard_torso' filename='libgazebo_yarp_controlboard.so'>
        <yarpConfigurationFile>model://icub/conf/gazebo_icub_torso.ini</yarpConfigurationFile>
      </plugin>
      <plugin name='controlboard_head' filename='libgazebo_yarp_controlboard.so'>
        <yarpConfigurationFile>model://icub/conf/gazebo_icub_head.ini</yarpConfigurationFile>
      </plugin>
      <plugin name='controlboard_left_arm_no_arm' filename='libgazebo_yarp_controlboard.so'>
        <yarpConfigurationFile>model://icub/conf/gazebo_icub_left_arm_no_hand_for_no_hand_model.ini</yarpConfigurationFile>
        <initialConfiguration>-0.52 0.52 0 0.785 0 0 0.698</initialConfiguration>
      </plugin>
      <plugin name='controlboard_right_arm_no_arm' filename='libgazebo_yarp_controlboard.so'>
        <yarpConfigurationFile>model://icub/conf/gazebo_icub_right_arm_no_hand_for_no_hand_model.ini</yarpConfigurationFile>
        <initialConfiguration>-0.52 0.52 0 0.785 0 0 0.698</initialConfiguration>
      </plugin>
      <plugin name='controlboard_left_leg' filename='libgazebo_yarp_controlboard.so'>
        <yarpConfigurationFile>model://icub/conf/gazebo_icub_left_leg.ini</yarpConfigurationFile>
      </plugin>
      <plugin name='controlboard_right_leg' filename='libgazebo_yarp_controlboard.so'>
        <yarpConfigurationFile>model://icub/conf/gazebo_icub_right_leg.ini</yarpConfigurationFile>
      </plugin>
      <plugin name='apply_external_wrench' filename='libgazebo_yarp_externalwrench.so'>
        <robotNamefromConfigFile>model://icub/conf/gazebo_icub_robotname.ini</robotNamefromConfigFile>
      </plugin>
      <pose frame=''>0 0 0.7 0 -0 0</pose>
    </model>
    <model name='chair'>
      <pose frame=''>0 0 0 0 -0 0</pose>
      <link name='low_part'>
        <pose frame=''>-0.003 0 0.202 0 0.12304 0</pose>
        <inertial>
          <mass>1</mass>
          <inertia>
            <ixx>1</ixx>
            <ixy>0</ixy>
            <ixz>0</ixz>
            <iyy>1</iyy>
            <iyz>0</iyz>
            <izz>1</izz>
          </inertia>
        </inertial>
        <collision name='collision_low'>
          <pose frame=''>0 0 0 0 -0 0</pose>
          <geometry>
            <box>
              <size>0.05 0.75 0.025</size>
            </box>
          </geometry>
          <max_contacts>10</max_contacts>
          <surface>
            <contact>
              <ode/>
            </contact>
            <bounce/>
            <friction>
              <torsional>
                <ode/>
              </torsional>
              <ode/>
            </friction>
          </surface>
        </collision>
        <visual name='visual_low'>
          <pose frame=''>0 0 0 0 -0 0</pose>
          <geometry>
            <box>
              <size>0.05 0.75 0.025</size>
            </box>
          </geometry>
        </visual>
        <self_collide>0</self_collide>
        <kinematic>0</kinematic>
      </link>
      <link name='high_part'>
        <pose frame=''>0 0 0.226 0 0.12304 0</pose>
        <inertial>
          <mass>1</mass>
          <inertia>
            <ixx>1</ixx>
            <ixy>0</ixy>
            <ixz>0</ixz>
            <iyy>1</iyy>
            <iyz>0</iyz>
            <izz>1</izz>
          </inertia>
        </inertial>
        <collision name='collision_high'>
          <pose frame=''>0 0 0 0 -0 0</pose>
          <geometry>
            <box>
              <size>0.05 0.75 0.025</size>
            </box>
          </geometry>
          <max_contacts>4</max_contacts>
          <surface>
            <contact>
              <ode>
                <soft_erp>0.2</soft_erp>
                <soft_cfm>0</soft_cfm>
                <kp>1.8e+06</kp>
                <kd>100</kd>
                <max_vel>100</max_vel>
                <min_depth>0.0001</min_depth>
              </ode>
            </contact>
            <friction>
              <ode>
                <mu>1</mu>
                <mu2>1</mu2>
                <fdir1>0 0 0</fdir1>
                <slip1>0</slip1>
                <slip2>0</slip2>
              </ode>
              <torsional>
                <ode/>
              </torsional>
            </friction>
            <bounce>
              <restitution_coefficient>0</restitution_coefficient>
              <threshold>100000</threshold>
            </bounce>
          </surface>
        </collision>
        <visual name='visual_high'>
          <pose frame=''>0 0 0 0 -0 0</pose>
          <material>
            <script>
              <name>Gazebo/Blue</name>
              <uri>__default__</uri>
            </script>
          </material>
          <geometry>
            <box>
              <size>0.05 0.75 0.025</size>
            </box>
          </geometry>
        </visual>
        <self_collide>0</self_collide>
        <kinematic>0</kinematic>
      </link>
      <joint name='sensor_joint' type='fixed'>
        <parent>low_part</parent>
        <child>high_part</child>
        <axis>
          <limit>
            <lower>0</lower>
            <upper>0</upper>
          </limit>
          <xyz>0 0 0</xyz>
          <use_parent_model_frame>0</use_parent_model_frame>
        </axis>
        <sensor name='chair_ft_sensor' type='force_torque'>
          <force_torque>
            <frame>child</frame>
            <measure_direction>parent_to_child</measure_direction>
          </force_torque>
          <always_on>1</always_on>
          <visualize>1</visualize>
          <update_rate>100</update_rate>
          <plugin name='chair_FT_plugin' filename='libgazebo_yarp_forcetorque.so'>
            <yarpConfigurationFile>model://chair/chair_gazebo_torque.ini</yarpConfigurationFile>
          </plugin>
        </sensor>
      </joint>
      <joint name='fixed to ground' type='fixed'>
        <parent>world</parent>
        <child>low_part</child>
        <axis>
          <limit>
            <lower>0</lower>
            <upper>0</upper>
          </limit>
          <xyz>0 0 0.4</xyz>
          <use_parent_model_frame>0</use_parent_model_frame>
        </axis>
      </joint>
    </model>
    <state world_name='default'>
      <sim_time>0 0</sim_time>
      <real_time>0 0</real_time>
      <wall_time>1494170562 613754077</wall_time>
      <iterations>0</iterations>
      <model name='chair'>
        <pose frame=''>-1e-06 -0 2e-06 -0 -0 -0</pose>
        <scale>1 1 1</scale>
        <link name='high_part'>
          <pose frame=''>1.1e-05 4e-06 0.229986 0 0.123041 0</pose>
          <velocity>-0.001122 -0.000194 0.001256 -7.9e-05 -4.6e-05 0.0001</velocity>
          <acceleration>-0.027115 0.618242 0.223695 -0.112795 -0.006554 0.199139</acceleration>
          <wrench>-0.027115 0.618242 0.223695 0 -0 0</wrench>
        </link>
        <link name='low_part'>
          <pose frame=''>-1e-06 -0 0.205002 0 0.12304 0</pose>
          <velocity>9.3e-05 1.2e-05 -0.000211 1.8e-05 9e-06 0</velocity>
          <acceleration>0.014367 -0.06886 -0.042399 0.02668 0.001609 -0.003145</acceleration>
          <wrench>0.014367 -0.06886 -0.042399 0 -0 0</wrench>
        </link>
      </model>
      <model name='ground_plane'>
        <pose frame=''>0 0 0 0 -0 0</pose>
        <scale>1 1 1</scale>
        <link name='link'>
          <pose frame=''>0 0 0 0 -0 0</pose>
          <velocity>0 0 0 0 -0 0</velocity>
          <acceleration>0 0 0 0 -0 0</acceleration>
          <wrench>0 0 0 0 -0 0</wrench>
        </link>
      </model>
      <model name='iCub'>
        <pose frame=''>-0.005275 -0.029628 0.418744 -0.003924 -0.124005 -3.11774</pose>
        <scale>1 1 1</scale>
        <link name='chest'>
          <pose frame=''>0.00935 -0.02939 0.447559 1.57476 0.298478 0.024582</pose>
          <velocity>0.002227 0.001208 -0.018331 0.006581 -0.067162 -0.001479</velocity>
          <acceleration>1.08745 0.006655 0.594708 -2.71807 0.016783 1.382</acceleration>
          <wrench>5.23064 0.032012 2.86055 0 -0 0</wrench>
        </link>
        <link name='eyes_tilt_link'>
          <pose frame=''>0.155231 -0.027049 0.72551 1.56661 -0.302017 -3.11699</pose>
          <velocity>-0.0052 -0.000791 -0.013991 0.009581 0.010546 -7.6e-05</velocity>
          <acceleration>-0.288488 0.252236 0.478264 0.985427 0.471284 2.30806</acceleration>
          <wrench>-0.002885 0.002522 0.004783 0 -0 0</wrench>
        </link>
        <link name='head'>
          <pose frame=''>0.071209 -0.028673 0.640665 -1.57498 -0.301941 -3.11699</pose>
          <velocity>-0.008297 -3.3e-05 -0.01116 0.008977 0.035758 2.7e-05</velocity>
          <acceleration>-0.173357 0.19457 0.781599 0.861365 -1.2198 2.33132</acceleration>
          <wrench>-0.520071 0.583711 2.3448 0 -0 0</wrench>
        </link>
        <link name='l_ankle_1'>
          <pose frame=''>0.152504 0.043912 0.044914 -2.99222 -1.54347 -0.124568</pose>
          <velocity>-0.006577 0.000579 -0.017624 0.001765 -0.138846 0.007838</velocity>
          <acceleration>1.06752 -1.22412 3.56194 0.709943 -0.822374 0.055799</acceleration>
          <wrench>0.796371 -0.913193 2.65721 0 -0 0</wrench>
        </link>
        <link name='l_ankle_2'>
          <pose frame=''>0.152504 0.043912 0.044914 -3.13862 0.027033 0.02486</pose>
          <velocity>-0.006576 0.000644 -0.017702 -0.039385 -0.139727 0.009106</velocity>
          <acceleration>0.126711 -0.615804 3.95488 0.998074 -1.55564 3.06235</acceleration>
          <wrench>0.033895 -0.164728 1.05793 0 -0 0</wrench>
        </link>
        <link name='l_elbow_1'>
          <pose frame=''>0.091271 0.144609 0.449104 -2.47551 -0.856063 -0.44365</pose>
          <velocity>-0.002752 0.001646 -0.01052 0.014619 -0.015062 -0.003337</velocity>
          <acceleration>-0.307008 0.417791 0.597933 -0.600716 0.850576 -0.943152</acceleration>
          <wrench>-0.030701 0.041779 0.059793 0 -0 0</wrench>
        </link>
        <link name='l_foot'>
          <pose frame=''>0.151501 0.043997 0.007927 -3.13862 0.027033 0.02486</pose>
          <velocity>-0.001418 -0.000711 -0.017849 -0.038869 -0.13958 0.00962</velocity>
          <acceleration>0.952922 -0.801545 3.22484 2.16238 -1.37513 -1.00338</acceleration>
          <wrench>0.565559 -0.475717 1.91395 0 -0 0</wrench>
        </link>
        <link name='l_forearm'>
          <pose frame=''>0.082392 0.148828 0.437776 -2.54284 -0.416966 1.66282</pose>
          <velocity>-0.002591 0.001867 -0.010746 0.007096 -0.017769 0.001588</velocity>
          <acceleration>-0.32253 0.331855 0.530702 -1.29418 0.591936 -0.473524</acceleration>
          <wrench>-0.169328 0.174224 0.278618 0 -0 0</wrench>
        </link>
        <link name='l_hand'>
          <pose frame=''>0.192447 0.190457 0.367022 -0.85609 0.904686 0.690726</pose>
          <velocity>-0.00141 0.002525 -0.008446 0.001391 -0.015112 -0.005724</velocity>
          <acceleration>-0.354209 0.172015 0.421972 -1.27235 0.640083 -0.3398</acceleration>
          <wrench>-0.075447 0.036639 0.08988 0 -0 0</wrench>
        </link>
        <link name='l_hip_1'>
          <pose frame=''>-0.021701 0.038564 0.300037 0.004044 0.211016 0.024206</pose>
          <velocity>-0.01301 -0.000256 -0.032018 -0.002858 -0.077291 -0.010028</velocity>
          <acceleration>-1.02015 3.0384 0.867672 0.79173 0.509716 0.041724</acceleration>
          <wrench>-0.769191 2.29095 0.654225 0 -0 0</wrench>
        </link>
        <link name='l_hip_2'>
          <pose frame=''>-0.021701 0.038564 0.300045 -3.12126 -1.35973 0.004829</pose>
          <velocity>-0.013014 -0.000329 -0.032267 -0.003479 -0.077008 0.008904</velocity>
          <acceleration>0.996069 2.83517 4.7951 0.992277 -0.651229 -2.85718</acceleration>
          <wrench>0.523932 1.4913 2.52222 0 -0 0</wrench>
        </link>
        <link name='l_hip_3'>
          <pose frame=''>0.043303 0.040225 0.286149 -3.12125 -1.35973 0.004818</pose>
          <velocity>-0.011646 -0.000238 -0.024892 -0.004153 -0.076324 0.008632</velocity>
          <acceleration>0.785677 1.91571 11.0123 -2.81914 -1.30044 0.667333</acceleration>
          <wrench>0.078568 0.191571 1.10123 0 -0 0</wrench>
        </link>
        <link name='l_lower_leg'>
          <pose frame=''>0.196862 0.044163 0.253244 -1.55126 -1.36101 0.005651</pose>
          <velocity>-0.008563 0.001216 -0.017176 -0.001413 -0.009566 0.008219</velocity>
          <acceleration>0.953616 0.262316 4.11202 1.33989 -0.652708 0.254313</acceleration>
          <wrench>1.20537 0.331568 5.19759 0 -0 0</wrench>
        </link>
        <link name='l_shoulder_1'>
          <pose frame=''>0.053923 0.081431 0.583388 0.886829 -1.47718 2.02969</pose>
          <velocity>-0.006544 0.000166 -0.013804 0.016903 -0.024377 -0.004946</velocity>
          <acceleration>-0.066578 0.371689 0.593448 -2.73695 1.51103 -2.81099</acceleration>
          <wrench>-0.012583 0.070249 0.112162 0 -0 0</wrench>
        </link>
        <link name='l_shoulder_2'>
          <pose frame=''>0.053923 0.081432 0.583383 3.07595 -0.45015 1.37647</pose>
          <velocity>-0.006457 8.1e-05 -0.013288 0.015201 -0.024361 -0.005132</velocity>
          <acceleration>-0.095459 0.423964 0.641225 2.57278 1.50704 -2.60758</acceleration>
          <wrench>-0.017087 0.075889 0.114779 0 -0 0</wrench>
        </link>
        <link name='l_shoulder_3'>
          <pose frame=''>0.053922 0.081434 0.583377 -2.7181 -0.170486 0.015693</pose>
          <velocity>-0.006356 -2.5e-05 -0.012729 0.01547 -0.023554 -0.007078</velocity>
          <acceleration>-0.138053 0.472564 0.656065 2.78197 1.0693 2.80429</acceleration>
          <wrench>-0.021558 0.073794 0.102449 0 -0 0</wrench>
        </link>
        <link name='l_upper_arm'>
          <pose frame=''>0.07878 0.109772 0.52483 -2.7181 -0.170485 0.015694</pose>
          <velocity>-0.00483 0.000717 -0.011888 0.015307 -0.023642 -0.007158</velocity>
          <acceleration>-0.219766 0.415959 0.590733 2.40921 1.09505 2.73517</acceleration>
          <wrench>-0.159955 0.302753 0.429961 0 -0 0</wrench>
        </link>
        <link name='l_upper_leg'>
          <pose frame=''>-0.021705 0.038557 0.300099 1.59018 -1.35963 0.005816</pose>
          <velocity>-0.011863 -0.000618 -0.035686 0.000269 -0.085603 0.008558</velocity>
          <acceleration>1.4465 1.67693 5.34352 2.9325 -1.29964 -1.71882</acceleration>
          <wrench>3.14613 3.64732 11.6222 0 -0 0</wrench>
        </link>
        <link name='l_wrist_1'>
          <pose frame=''>0.192447 0.190457 0.367021 -1.07859 0.541387 0.361615</pose>
          <velocity>-0.001402 0.002507 -0.008385 0.001387 -0.01508 -0.005707</velocity>
          <acceleration>-0.330672 0.265362 0.47571 -1.29982 0.588231 -0.478881</acceleration>
          <wrench>-0.033067 0.026536 0.047571 0 -0 0</wrench>
        </link>
        <link name='left_eye_link'>
          <pose frame=''>0.154437 0.006942 0.725646 3.13742 -0.302017 -3.11699</pose>
          <velocity>-0.005219 -0.000793 -0.013715 0.009442 0.010577 -0.000501</velocity>
          <acceleration>-0.259747 0.249581 0.621109 0.872964 0.472561 2.05154</acceleration>
          <wrench>-0.002597 0.002496 0.006211 0 -0 0</wrench>
        </link>
        <link name='neck_1'>
          <pose frame=''>0.068389 -0.028705 0.631605 -3.12884 -1.26882 0.011244</pose>
          <velocity>-0.009056 -8e-06 -0.011952 0.003821 0.035517 -0.000965</velocity>
          <acceleration>-0.685023 0.570919 0.929526 -0.934962 -1.01724 -1.39874</acceleration>
          <wrench>-0.068502 0.057092 0.092953 0 -0 0</wrench>
        </link>
        <link name='neck_2'>
          <pose frame=''>0.071207 -0.028673 0.640657 0.30194 -0.003983 1.59416</pose>
          <velocity>-0.008084 -2.6e-05 -0.010397 0.008222 0.03608 -0.002343</velocity>
          <acceleration>-0.662723 0.679103 0.789791 0.824944 -1.22055 2.37408</acceleration>
          <wrench>-0.066272 0.06791 0.078979 0 -0 0</wrench>
        </link>
        <link name='r_ankle_1'>
          <pose frame=''>0.155983 -0.092669 0.044602 0.129722 -1.54647 -0.106053</pose>
          <velocity>-0.00441 0.000172 -0.01177 0.00156 -0.089651 0.006798</velocity>
          <acceleration>-0.425394 -1.06814 -0.053371 1.48091 -1.12177 2.8081</acceleration>
          <wrench>-0.317344 -0.796836 -0.039815 0 -0 0</wrench>
        </link>
        <link name='r_ankle_2'>
          <pose frame=''>0.155983 -0.092668 0.044602 -3.13906 0.024119 0.023709</pose>
          <velocity>-0.004361 0.000197 -0.011721 -0.023277 -0.090292 0.00749</velocity>
          <acceleration>-0.307124 -0.855925 0.049973 0.218082 -1.37327 2.6416</acceleration>
          <wrench>-0.082156 -0.22896 0.013368 0 -0 0</wrench>
        </link>
        <link name='r_elbow_1'>
          <pose frame=''>0.099322 -0.199358 0.447794 0.655575 0.859452 -2.65907</pose>
          <velocity>-0.00286 -0.001458 -0.011465 -0.017526 -0.018076 0.001248</velocity>
          <acceleration>-0.22081 0.653051 1.03085 2.04203 1.01658 -1.55021</acceleration>
          <wrench>-0.022081 0.065305 0.103085 0 -0 0</wrench>
        </link>
        <link name='r_foot'>
          <pose frame=''>0.155089 -0.092595 0.007613 -3.13906 0.024119 0.023712</pose>
          <velocity>-0.000942 -0.000641 -0.011816 -0.02331 -0.09055 0.00773</velocity>
          <acceleration>-0.290358 -0.652115 0.094926 0.910898 -1.02201 -2.43395</acceleration>
          <wrench>-0.172328 -0.38703 0.056339 0 -0 0</wrench>
        </link>
        <link name='r_forearm'>
          <pose frame=''>0.090648 -0.203901 0.436433 0.599358 0.409309 1.52583</pose>
          <velocity>-0.002674 -0.001699 -0.011693 -0.010892 -0.020064 -0.003051</velocity>
          <acceleration>-0.305083 0.661081 0.945814 0.50263 1.49744 -0.555496</acceleration>
          <wrench>-0.160169 0.347067 0.496553 0 -0 0</wrench>
        </link>
        <link name='r_hand'>
          <pose frame=''>0.202516 -0.239791 0.365378 -2.27572 0.909439 -0.636205</pose>
          <velocity>-0.001367 -0.002795 -0.009009 -0.0034 -0.016196 0.006791</velocity>
          <acceleration>-0.454896 0.584736 0.794545 -0.28839 1.23067 -1.46177</acceleration>
          <wrench>-0.096893 0.124549 0.169238 0 -0 0</wrench>
        </link>
        <link name='r_hip_1'>
          <pose frame=''>-0.018519 -0.09759 0.299505 -3.13767 0.209729 0.024187</pose>
          <velocity>-0.014476 -0.00078 -0.033264 0.007175 -0.12291 -0.010313</velocity>
          <acceleration>-0.554367 2.89087 -0.342426 0.694373 -1.52355 -2.52798</acceleration>
          <wrench>-0.417993 2.17972 -0.258189 0 -0 0</wrench>
        </link>
        <link name='r_hip_2'>
          <pose frame=''>-0.018519 -0.097591 0.299511 -3.1231 -1.36103 0.005388</pose>
          <velocity>-0.014442 -0.00081 -0.03418 0.010396 -0.124162 0.003388</velocity>
          <acceleration>-2.3229 2.65352 -3.96238 -2.2931 0.225248 -1.18298</acceleration>
          <wrench>-1.22185 1.39575 -2.08421 0 -0 0</wrench>
        </link>
        <link name='r_hip_3'>
          <pose frame=''>0.046503 -0.09601 0.285688 -3.12311 -1.36102 0.0054</pose>
          <velocity>-0.012199 -0.0006 -0.03198 0.010394 -0.125228 0.004546</velocity>
          <acceleration>-0.916597 1.48462 -11.3035 0.500409 1.046 2.96409</acceleration>
          <wrench>-0.09166 0.148462 -1.13035 0 -0 0</wrench>
        </link>
        <link name='r_lower_leg'>
          <pose frame=''>0.200108 -0.092282 0.252981 -1.55562 -1.36212 0.008773</pose>
          <velocity>-0.008582 0.000473 -0.010909 -6.7e-05 -0.019898 0.006845</velocity>
          <acceleration>-0.806094 0.476491 0.016372 1.58633 0.360787 2.54309</acceleration>
          <wrench>-1.0189 0.602285 0.020695 0 -0 0</wrench>
        </link>
        <link name='r_shoulder_1'>
          <pose frame=''>0.059086 -0.139029 0.582553 2.22285 -1.47026 -1.95109</pose>
          <velocity>-0.006855 0.000397 -0.015001 -0.006466 -0.023893 0.002526</velocity>
          <acceleration>0.200638 0.352301 1.18849 0.91846 0.945332 -0.06137</acceleration>
          <wrench>0.037921 0.066585 0.224625 0 -0 0</wrench>
        </link>
        <link name='r_shoulder_2'>
          <pose frame=''>0.059085 -0.13903 0.582548 0.06745 -0.442663 -1.33042</pose>
          <velocity>-0.006766 0.000501 -0.014498 -0.017496 -0.027314 0.001916</velocity>
          <acceleration>0.19268 0.407566 1.29815 -2.40457 -1.53788 0.350241</acceleration>
          <wrench>0.03449 0.072954 0.23237 0 -0 0</wrench>
        </link>
        <link name='r_shoulder_3'>
          <pose frame=''>0.059084 -0.139031 0.582542 2.72587 -0.170515 0.029813</pose>
          <velocity>-0.006663 0.000631 -0.013948 -0.017971 -0.026165 0.004724</velocity>
          <acceleration>0.077067 0.508633 1.18128 -1.47158 0.885303 0.969512</acceleration>
          <wrench>0.011945 0.078838 0.183099 0 -0 0</wrench>
        </link>
        <link name='r_upper_arm'>
          <pose frame=''>0.08523 -0.165725 0.523783 2.72587 -0.170515 0.029812</pose>
          <velocity>-0.005055 -0.000325 -0.012963 -0.017803 -0.026247 0.004802</velocity>
          <acceleration>-0.052358 0.530261 1.12072 -1.07597 0.857436 1.04376</acceleration>
          <wrench>-0.038169 0.38656 0.817008 0 -0 0</wrench>
        </link>
        <link name='r_upper_leg'>
          <pose frame=''>-0.018526 -0.097597 0.29955 1.58587 -1.36096 0.008892</pose>
          <velocity>-0.014894 -0.00057 -0.0401 0.003122 -0.133643 0.004202</velocity>
          <acceleration>-2.21328 1.85707 -2.47442 1.63437 -0.298691 -1.97975</acceleration>
          <wrench>-4.81389 4.03913 -5.38186 0 -0 0</wrench>
        </link>
        <link name='r_wrist_1'>
          <pose frame=''>0.202515 -0.239792 0.365377 2.05455 -0.54395 2.83115</pose>
          <velocity>-0.00136 -0.002776 -0.008949 -0.003396 -0.016164 0.006775</velocity>
          <acceleration>-0.367707 0.647963 0.840405 -0.083199 1.19475 -1.33884</acceleration>
          <wrench>-0.036771 0.064796 0.08404 0 -0 0</wrench>
        </link>
        <link name='right_eye_link'>
          <pose frame=''>0.156025 -0.061039 0.725376 3.13742 -0.302016 -3.11699</pose>
          <velocity>-0.005276 -0.000792 -0.014503 0.009366 0.010646 -0.000547</velocity>
          <acceleration>-0.315026 0.243345 0.351034 0.810023 0.473352 2.07116</acceleration>
          <wrench>-0.00315 0.002433 0.00351 0 -0 0</wrench>
        </link>
        <link name='root_link'>
          <pose frame=''>-0.005275 -0.029628 0.418744 -0.003924 -0.124005 -3.11774</pose>
          <velocity>0.000176 0.000435 -0.033977 -0.005189 0.115915 -0.008796</velocity>
          <acceleration>2.90681 -1.67051 -0.1368 -0.168988 -0.484078 -1.98034</acceleration>
          <wrench>13.7201 -7.88483 -0.645697 0 -0 0</wrench>
        </link>
        <link name='torso_1'>
          <pose frame=''>-0.005303 -0.029623 0.418634 0.013214 -1.27229 0.010733</pose>
          <velocity>0.002866 0.00096 -0.023461 -0.006482 -0.067028 -0.00941</velocity>
          <acceleration>2.67483 0.366906 -0.019692 -2.91484 -1.56151 -1.38028</acceleration>
          <wrench>0.267483 0.036691 -0.001969 0 -0 0</wrench>
        </link>
        <link name='torso_2'>
          <pose frame=''>0.004088 -0.029518 0.449145 2.84311 0.003785 -1.5474</pose>
          <velocity>0.002755 0.001411 -0.01567 0.003206 -0.067361 -0.012384</velocity>
          <acceleration>2.10002 0.381906 0.165891 0.874428 -0.127781 2.14922</acceleration>
          <wrench>0.210002 0.038191 0.016589 0 -0 0</wrench>
        </link>
      </model>
      <light name='sun'>
        <pose frame=''>0 0 10 0 -0 0</pose>
      </light>
    </state>
    <gui fullscreen='0'>
      <camera name='user_camera'>
        <pose frame=''>0.00402 1.02195 0.481832 0 0.115641 -1.23977</pose>
        <view_controller>orbit</view_controller>
        <projection_type>perspective</projection_type>
      </camera>
    </gui>
  </world>
</sdf>
